Workbook

Sheet 源数据
A1: 2018年度酒便利平台泸州老窖销量占比情况
A2: 全国酒便利周明细—河南 | J2: 国窖进2154；国窖出2161。（箱）
A3: 序号 | B3: 商品编码 | C3: 商品名称 | D3: 规格 | E3: 单价 | F3: 全年计划总量(瓶) | G3: 全年计划采购总金额 | H3: 成交价 | I3: 20171101-20181031 | K3: 20170501-20171031 | M3: 20180501-20181031 | R3: 本品情况 | W3: 竞品情况
I4: 出库数量 | J4: 出库金额 | K4: 出库数量 | L4: 出库金额 | M4: 出库数量 | N4: 出库金额 | Q4: 酒便利各公司白酒销售额（元） | R4: 酒便利各区域白酒销售总金额（元） | S4: 我司白酒在各区域销售额（元） | T4: 占比 | U4: 国窖销售额 | V4: 国窖占比 | W4: 普五销售额 | X4: 普五占比 | Y4: 普剑销售额 | Z4: 普剑占比 | AA4: 52海之蓝销售额 | AB4: 海之蓝占比
A5: 1 | B5: 101010397 | C5: 38°国窖1573 500ml | D5: 500ml*6 | E5: 530 | F5: 0 | G5: 0 | Q5: 河南酒便利白酒销售额 | R5: 4.3349845e+08 | S5: 24735880 | T5: =S5/R5 -> 0.057061057 | U5: 9710280 | V5: =U5/R5 -> 0.022399803 | W5: 55255963 | X5: =W5/R5 -> 0.12746519 | Y5: 55386699 | Z5: =Y5/R5 -> 0.12776677 | AA5: 15423160 | AB5: =AA5/R5 -> 0.03557835
A6: 2 | B6: 101010099 | C6: 52°国窖1573 500ml | D6: 500ml*6 | E6: 740 | F6: 15600 | G6: 11544000 | H6: 830.06 | I6: 13122 | J6: 10892047 | K6: 5289 | L6: 4390187.3 | M6: 4995 | N6: 4146149.7 | Q6: 北京酒便利白酒销售额 | R6: 1.1555258e+08 | S6: 8470335.2 | T6: =S6/R6 -> 0.073302863 | U6: 5311904.6 | V6: =U6/R6 -> 0.045969587 | W6: 9755379 | X6: =W6/R6 -> 0.08442372 | Y6: 3324629.5 | Z6: =Y6/R6 -> 0.028771573
A7: 3 | B7: 101010114 | C7: *52°百年泸州老窖酒窖龄30年500ml | D7: 500ml*6 | E7: 165 | F7: 7812 | G7: 1288980 | H7: 210.82 | I7: 2770 | J7: 583971.4 | K7: 1131 | L7: 238437.42 | M7: 1269 | N7: 267530.58 | Q7: 西安酒便利白酒销售额 | R7: 33470167 | S7: 3585472.7 | T7: =S7/R7 -> 0.10712443 | U7: 2712408.9 | V7: =U7/R7 -> 0.0810396 | W7: 4432500 | X7: =W7/R7 -> 0.13243137 | Y7: 1414867.5 | Z7: =Y7/R7 -> 0.042272496
A8: 4 | B8: 101010115 | C8: 52°百年泸州老窖酒窖龄60年500ml | D8: 500ml*6 | E8: 200 | F8: 15612 | G8: 3122400 | H8: 264.02 | I8: 5498 | J8: 1451582 | K8: 2544 | L8: 671666.88 | M8: 2334 | N8: 616222.68 | Q8: 徐州酒便利白酒销售额 | R8: 4535723.1 | S8: 139923.1 | T8: =S8/R8 -> 0.030849127 | U8: 94002.44 | V8: =U8/R8 -> 0.020724907 | W8: 428653.68 | X8: =W8/R8 -> 0.094506139 | Y8: 64774.29 | Z8: =Y8/R8 -> 0.014280918
A9: 5 | B9: 101010294 | C9: 38°泸州老窖泸州百年30年窖龄500ml | D9: 500ml*6 | E9: 145 | F9: 0 | G9: 0 | Q9: 总计 | R9: =SUM(R5:R8) -> 5.8705693e+08 | S9: =SUM(S5:S8) -> 36931611 | T9: =SUM(T5:T8) -> 0.26833748 | U9: =SUM(U5:U8) -> 17828596 | V9: =SUM(V5:V8) -> 0.1701339 | W9: =SUM(W5:W8) -> 69872496 | X9: =SUM(X5:X8) -> 0.43882642 | Y9: =SUM(Y5:Y8) -> 60190970 | Z9: =SUM(Z5:Z8) -> 0.21309176
A10: 6 | B10: 101010297 | C10: 38°泸州老窖百年60年窖龄500ml | D10: 500ml*6 | E10: 180 | F10: 0 | G10: 0
A11: 7 | B11: 101010036 | C11: 52°泸州老窖特曲500ml | D11: 500ml*6 | E11: 168 | F11: 85020 | G11: 14283360 | H11: 203.03 | I11: 46072 | J11: 9353998.2 | K11: 21635 | L11: 4392554 | M11: 21280 | N11: 4320478.4 | Q11: 酒便利各公司葡萄酒销售额（元） | R11: 酒便利各区域葡萄酒销售总金额（元） | S11: 我司葡萄酒在各区域销售额（元） | T11: 占比 | U11: 舒富销售额 | V11: 舒富占比
A12: 8 | B12: 101010024 | C12: 52°泸州老窖头曲500ml | D12: 500ml*6 | E12: 37.87 | F12: 39000 | G12: 1476930 | H12: 60.09 | I12: 21460 | J12: 1289531.4 | K12: 7817 | L12: 469723.53 | M12: 9236 | N12: 554991.24 | Q12: 河南酒便利葡萄酒销售额 | R12: 44379852 | S12: 3716238.3 | T12: =S12/R12 -> 0.083737061 | U12: 2314892.3 | V12: =U12/R12 -> 0.052160885
A13: 9 | B13: 101010503 | C13: 52°泸州老窖精品头曲D9 500ml | D13: 500ml*6 | E13: 75 | F13: 7962 | G13: 597150 | H13: 144.86 | I13: 2772 | J13: 401551.92 | K13: 1804 | L13: 261327.44 | M13: 1505 | N13: 218014.3 | Q13: 北京酒便利葡萄酒销售额 | R13: 32833504 | S13: 890240.86 | T13: =S13/R13 -> 0.027113794 | U13: 762937.84 | V13: =U13/R13 -> 0.023236565
A14: 10 | B14: 101010502 | C14: 52°泸州老窖精品头曲D6 500ml | D14: 500ml*6 | E14: 63 | F14: 15606 | G14: 983178 | H14: 94.45 | I14: 2731 | J14: 257942.95 | K14: 718 | L14: 67815.1 | M14: 1235 | N14: 116645.75 | Q14: 西安酒便利葡萄酒销售额 | R14: 4024733 | S14: 486809.32 | T14: =S14/R14 -> 0.12095444 | U14: 360249.09 | V14: =U14/R14 -> 0.089508817
A15: 11 | B15: 101010501 | C15: *42°泸小二FOR ME（彩色）酒125ml | D15: 125ml*24 | E15: 11 | F15: 0 | G15: 0 | H15: 11.93 | I15: 6343 | J15: 75671.99 | K15: 3600 | L15: 42948 | M15: 1564 | N15: 18658.52 | Q15: 徐州酒便利葡萄酒销售额 | R15: 962149.5 | S15: 40479.3 | T15: =S15/R15 -> 0.042071736 | U15: 40479.3 | V15: =U15/R15 -> 0.042071736
A16: 12 | B16: 101010504 | C16: 42°泸州老窖二曲白酒蓝瓶装 500ml | D16: 500ml*6 | E16: 12 | F16: 0 | G16: 0 | H16: 19.93 | I16: 1986 | J16: 39580.98 | K16: 743 | L16: 14807.99 | M16: 767 | N16: 15286.31 | Q16: 总计 | R16: =SUM(R12:R15) -> 82200238 | S16: =SUM(S12:S15) -> 5133767.8 | T16: =SUM(T12:T15) -> 0.27387703 | U16: =SUM(U12:U15) -> 3478558.6 | V16: =SUM(V12:V15) -> 0.206978
A17: 13 | B17: 101010521 | C17: 52°国窖1573曾娜大师鉴藏版500ml | D17: 500ml*6 | E17: 740 | F17: 0 | G17: 0 | H17: 928.61 | I17: 201 | J17: 186650.61 | M17: 82 | N17: 76146.02
A18: 14 | B18: 101010525 | C18: 52°泸州老窖2018农历戊戌年金狗佑财1.088L | D18: 1.088L*3 | E18: 468 | F18: 0 | G18: 0 | H18: 408.05 | I18: 112 | J18: 45701.6 | M18: 25 | N18: 10201.25 | Q18: 区域 | R18: 白酒销量（瓶） | U18: 葡萄酒销量（瓶）
A19: 15 | B19: 101020055 | C19: 52°泸州老窖中秋丁酉年节庆酒1L | D19: 1L*3 | E19: 268 | F19: 0 | G19: 0 | H19: 88.85 | I19: 261 | J19: 23189.85 | K19: 769 | L19: 68325.65 | M19: 46 | N19: 4087.1 | R19: 2017.5.1-2017.10.31 | S19: 2018.5.1-2018.10.31 | T19: 同比 | U19: 2017.5.1-2017.10.31 | V19: 2018.5.1-2018.10.31 | W19: 同比
A20: 16 | B20: 101020063 | C20: 53°国窖国韵1L | D20: 1L*1 | E20: 2220 | F20: 0 | G20: 0 | H20: 2536.98 | I20: 53 | J20: 134459.94 | M20: 49 | N20: 124312.02 | Q20: 河南酒便利 | R20: 46050 | S20: 44387 | T20: =(S20-R20)/R20 -> -0.036112921 | U20: 5524 | V20: 31235 | W20: =(V20-U20)/U20 -> 4.6544171
A21: 17 | B21: 103090047 | C21: *22°桃花醉配制酒（时尚版）500ml | D21: 500ml*6 | E21: 85 | F21: 0 | G21: 0 | Q21: 北京酒便利 | R21: 7163 | S21: 10368 | T21: =(S21-R21)/R21 -> 0.44743822 | U21: 225 | V21: 4799 | W21: =(V21-U21)/U21 -> 20.328889
A22: 18 | B22: 103090048 | C22: *22°桃花醉配制酒（仙侠版）500ml | D22: 500ml*6 | E22: 85 | F22: 0 | G22: 0 | Q22: 西安酒便利 | R22: 2063 | S22: 5377 | T22: =(S22-R22)/R22 -> 1.6063984 | U22: 44 | V22: 3239 | W22: =(V22-U22)/U22 -> 72.613636
A23: 老窖白酒合计 | I23: =SUM(I6:I20) -> 103381 | J23: =SUM(J6:J20) -> 24735880 | K23: =SUM(K6:K20) -> 46050 | L23: =SUM(L6:L20) -> 10617793 | M23: =SUM(M6:M20) -> 44387 | N23: =SUM(N6:N20) -> 10488724 | Q23: 徐州酒便利 | R23: 1 | S23: 287 | T23: =(S23-R23)/R23 -> 286 | U23: 0 | V23: 351 | W23: =(V23-U23)/U23 -> #DIV/0!
A24: 河南酒便利平台白酒合计 | I24: 1869244 | J24: 4.3349845e+08 | Q24: 总计 | R24: =SUM(R20:R23) -> 55277 | S24: =SUM(S20:S23) -> 60419 | T24: =(S24-R24)/R24 -> 0.093022414 | U24: =SUM(U20:U23) -> 5793 | V24: =SUM(V20:V23) -> 39624 | W24: =(V24-U24)/U24 -> 5.8399793
A25: 老窖白酒在河南酒便利占比 | I25: =I23/I24 -> 0.055306316 | J25: =J23/J24 -> 0.057061057
C26: 52°国窖1573 500ml | D26: 500ml*6 | H26: 740 | I26: 13122 | J26: =H26*I26 -> 9710280 | Q26: 区域 | R26: 52°五粮液普装500ml（瓶） | U26: 52°剑南春普装500ml（瓶）
J27: =J26/J24 -> 0.022399803 | R27: 2017.5.1-2017.10.31 | S27: 2018.5.1-2018.10.31 | T27: 同比 | U27: 2017.5.1-2017.10.31 | V27: 2018.5.1-2018.10.31 | W27: 同比
C28: 52°泸州老窖特曲500ml | D28: 500ml*6 | H28: 168 | I28: 46072 | J28: =H28*I28 -> 7740096 | Q28: 河南酒便利 | R28: 29753 | S28: 27101 | T28: =(S28-R28)/R28 -> -0.089133869 | U28: 64698 | V28: 66934 | W28: =(V28-U28)/U28 -> 0.034560574
J29: =J28/J24 -> 0.017854956 | Q29: 北京酒便利 | R29: 3578 | S29: 5622 | T29: =(S29-R29)/R29 -> 0.57126887 | U29: 3662 | V29: 4481 | W29: =(V29-U29)/U29 -> 0.22364828
A30: 竞品信息 | B30: 101010002 | C30: 52°剑南春普装500ml | D30: 500ml*6 | H30: =VLOOKUP(B30,河南!G:I,3,0) -> 379.66 | I30: 145885 | J30: =H30*I30 -> 55386699 | K30: 64698 | L30: 24563243 | M30: 66934 | N30: 25412162 | Q30: 西安酒便利 | R30: 961 | S30: 2603 | T30: =(S30-R30)/R30 -> 1.7086368 | U30: 1089 | V30: 1685 | W30: =(V30-U30)/U30 -> 0.54729109
J31: =J30/J24 -> 0.12776677 | Q31: 徐州酒便利 | R31: 8 | S31: 333 | T31: =(S31-R31)/R31 -> 40.625 | U31: 0 | V31: 100 | W31: =(V31-U31)/U31 -> #DIV/0!
A32: 竞品信息 | B32: 101010001 | C32: 52°五粮液普装500ml | D32: 500ml*6 | H32: =VLOOKUP(B32,河南!G:I,3,0) -> 879.83 | I32: 62803 | J32: =H32*I32 -> 55255963 | K32: 29753 | L32: 26177582 | M32: 27101 | N32: 23844273 | Q32: 总计 | R32: =SUM(R28:R31) -> 34300 | S32: =SUM(S28:S31) -> 35659 | T32: =SUM(T28:T31) -> 42.815772 | U32: =SUM(U28:U31) -> 69449 | V32: =SUM(V28:V31) -> 73200 | W32: =(V32-U32)/U32 -> 0.054010857
J33: =J32/J24 -> 0.12746519
A34: 竞品信息 | B34: 101010004 | C34: 52°洋河天之蓝480ml | D34: 480ml*6 | H34: =VLOOKUP(B34,河南!G:I,3,0) -> 346.05 | I34: 15225 | J34: =H34*I34 -> 5268611.2 | K34: 6887 | L34: 2383246.4 | M34: 7096 | N34: 2455570.8
J35: =J34/J24 -> 0.012153703
A36: 竞品信息 | B36: 101010098 | C36: 52°洋河海之蓝480ml | D36: 480ml*6 | H36: =VLOOKUP(B36,河南!G:I,3,0) -> 145.4 | I36: 106074 | J36: =H36*I36 -> 15423160 | K36: 50409 | L36: =H36*K36 -> 7329468.6 | M36: 47800 | N36: =H36*M36 -> 6950120
J37: =J36/J24 -> 0.03557835
A38: 1 | B38: 104020590 | C38: 舒富红葡萄酒750ml | D38: 750ml*6 | E38: 40.91 | F38: 53298 | G38: 2398410 | H38: 90.42 | I38: 56585 | J38: =E38*I38 -> 2314892.3 | K38: 3133 | L38: 283285.86 | M38: 19866 | N38: 1796283.7
A39: 2 | B39: 104020591 | C39: 希拉谷西拉红葡萄酒750ml | D39: 750ml*6 | E39: 90 | F39: 10008 | G39: 900720 | H39: 161.46 | I39: 14256 | J39: =E39*I39 -> 1283040 | K39: 1601 | L39: 258497.46 | M39: 10846 | N39: 1751195.2
A40: 3 | B40: 104020592 | C40: 希拉谷庄园西拉红葡萄酒750ml | D40: 750ml*6 | E40: 149 | F40: 7800 | G40: 1162200 | H40: 381.29 | I40: 794 | J40: =E40*I40 -> 118306 | K40: 790 | L40: 301219.1 | M40: 523 | N40: 199414.67
...

Sheet 河南
B2: 商品大类 | C2: 商品类别 | D2: 商品名称 | E2: 规格 | F2: 单位 | G2: 商品编码 | H2: 数量 | I2: 成交均价 | J2: 销售额 | K2: 成本 | L2: 毛利 | M2: 毛利率 | N2: 单品客流量 | O2: 销售门店数
H3: 1821277 | I3: 231.50861 | J3: 4.216413e+08 | K3: 3.524861e+08 | L3: 69155200 | O3: 21350
B4: 白酒 | C4: 白酒-浓香型 | D4: 52°五粮液普装500ml | E4: 500ml*6 | F4: 瓶 | G4: 101010001 | H4: 61601 | I4: 879.83 | J4: 54198683 | K4: 49533919 | L4: 4664763.3 | M4: 0.086 | N4: 14296 | O4: 143
B5: 白酒 | C5: 白酒-浓香型 | D5: 52°剑南春普装500ml | E5: 500ml*6 | F5: 瓶 | G5: 101010002 | H5: 142696 | I5: 379.66 | J5: 54176228 | K5: 49042652 | L5: 5133576.1 | M5: 0.0947 | N5: 38898 | O5: 142
B6: 白酒 | C6: 白酒-酱香型 | D6: 53°飞天茅台酒500ml | E6: 500ml*6 | F6: 瓶 | G6: 101010134 | H6: 32602 | I6: 1479.4 | J6: 48231255 | K6: 45388988 | L6: 2842267.1 | M6: 0.0589 | N6: 5904 | O6: 140
B7: 白酒 | C7: 白酒-浓香型 | D7: 52°五粮液1618 500ml | E7: 500ml*6 | F7: 瓶 | G7: 101010117 | H7: 39916 | I7: 886.42 | J7: 35382307 | K7: 32427773 | L7: 2954533.8 | M7: 0.0835 | N7: 8946 | O7: 143
B8: 白酒 | C8: 白酒其它 | D8: 52°洋河海之蓝480ml | E8: 480ml*6 | F8: 瓶 | G8: 101010098 | H8: 103500 | I8: 145.4 | J8: 15048872 | K8: 12312296 | L8: 2736575.3 | M8: 0.1818 | N8: 41203 | O8: 143
B9: 白酒 | C9: 白酒其它 | D9: 46°+70°仰韶彩陶坊地利(450ml+50ml) | E9: (450ml+50ml)*6 | F9: 瓶 | G9: 101010104 | H9: 68420 | I9: 206.46 | J9: 14125983 | K9: 11402711 | L9: 2723271.7 | M9: 0.1927 | N9: 24179 | O9: 143
B10: 白酒 | C10: 白酒其它 | D10: 46°+70°仰韶彩陶坊人和(450m+50ml） | E10: (450ml+50ml)*6 | F10: 瓶 | G10: 101010105 | H10: 119189 | I10: 110.05 | J10: 13117253 | K10: 9512567.7 | L10: 3604684.9 | M10: 0.2748 | N10: 51819 | O10: 143
B11: 白酒 | C11: 白酒-浓香型 | D11: 52°国窖1573 500ml | E11: 500ml*6 | F11: 瓶 | G11: 101010099 | H11: 12787 | I11: 830.46 | J11: 10619033 | K11: 9380443.9 | L11: 1238589.1 | M11: 0.1166 | N11: 2425 | O11: 140
B12: 白酒 | C12: 白酒-浓香型 | D12: 52°舍得酒500ml（HN） | E12: 500ml*6 | F12: 瓶 | G12: 101010019 | H12: 23597 | I12: 417.53 | J12: 9852416.8 | K12: 8198524.1 | L12: 1653892.7 | M12: 0.1678 | N12: 8260 | O12: 141
B13: 白酒 | C13: 白酒-浓香型 | D13: 52°泸州老窖特曲500ml | E13: 500ml*6 | F13: 瓶 | G13: 101010036 | H13: 45184 | I13: 203.15 | J13: 9178914.9 | K13: 6983414.8 | L13: 2195500.1 | M13: 0.2391 | N13: 14702 | O13: 143
B14: 白酒 | C14: 白酒-酱香型 | D14: 43°飞天茅台500ml | E14: 500ml*6 | F14: 瓶 | G14: 101010158 | H14: 7003 | I14: 932.34 | J14: 6529143.5 | K14: 5084619.6 | L14: 1444523.9 | M14: 0.2212 | N14: 1860 | O14: 129
B15: 白酒 | C15: 白酒-浓香型 | D15: 52°洋河天之蓝480ml | E15: 480ml*6 | F15: 瓶 | G15: 101010004 | H15: 14957 | I15: 346.05 | J15: 5175829 | K15: 4187330.1 | L15: 988498.89 | M15: 0.1909 | N15: 5828 | O15: 143
... B77: 白酒 | C77: 白酒-浓香型 | D77: 52°小糊涂神500ml | E77: 500ml*12 | F77: 瓶 | G77: 101010097 | H77: 8548 | I77: 77.74 | J77: 664501.1 | K77: 494851.52 | L77: 169649.58 | M77: 0.2553 | N77: 4473 | O77: 141
B78: 白酒 | C78: 白酒-酱香型 | D78: 53°赖茅重沙500ml | F78: 瓶 | G78: 101010555 | H78: 2396 | I78: 273.18 | J78: 654542 | K78: 364429.23 | L78: 290112.77 | M78: 0.4432 | N78: 1125 | O78: 125
B79: 白酒 | C79: 白酒-酱香型 | D79: *53°飞天茅台三十年500ml | E79: 500ml*6 | F79: 瓶 | G79: 101010157 | H79: 55 | I79: 11735.73 | J79: 645465 | K79: 543145.5 | L79: 102319.5 | M79: 0.1585 | N79: 22 | O79: 13
B80: 白酒 | C80: 白酒其它 | D80: 40°江小白100ml | E80: 100ml*24 | F80: 瓶 | G80: 101010619 | H80: 33373 | I80: 17.95 | J80: 598911.3 | K80: 391094.31 | L80: 207816.99 | M80: 0.3469 | N80: 10959 | O80: 140
B81: 白酒 | C81: 白酒-浓香型 | D81: 52°百年泸州老窖酒窖龄30年500ml | E81: 500ml*6 | F81: 瓶 | G81: 101010111 | H81: 2715 | I81: 210.86 | J81: 572472.4 | K81: 440937.01 | L81: 131535.39 | M81: 0.2297 | N81: 944 | O81: 131
B82: 白酒 | C82: 白酒-浓香型 | D82: 52°剑南原浆酒500ml | E82: 500ml*6 | F82: 瓶 | G82: 101010561 | H82: 3783 | I82: 147.59 | J82: 558321 | K82: 359663.4 | L82: 198657.6 | M82: 0.3558 | N82: 2233 | O82: 132
B83: 白酒 | C83: 白酒-浓香型 | D83: 52°五粮液六和液盛典装500ml | E83: 500ml*6 | F83: 瓶 | G83: 101010116 | H83: 3954 | I83: 140.64 | J83: 556093 | K83: 424623.83 | L83: 131469.17 | M83: 0.2364 | N83: 1473 | O83: 121
B84: 白酒 | C84: 白酒-酱香型 | D84: 53°茅台王子酒（酱香经典）500ml | E84: 500ml*6 | F84: 瓶 | G84: 101010550 | H84: 2164 | I84: 252.69 | J84: 546831 | K84: 385414.78 | L84: 161416.22 | M84: 0.2951 | N84: 494 | O84: 75
B85: 白酒 | C85: 白酒-浓酱兼香型 | D85: 53°白云边四星陈酿500ml | E85: 500ml*6 | F85: 瓶 | G85: 101010124 | H85: 7221 | I85: 75.28 | J85: 543562.2 | K85: 395867.76 | L85: 147694.44 | M85: 0.2717 | N85: 3901 | O85: 136
B86: 白酒 | C86: 白酒-酱香型 | D86: 53°飞天茅台玫瑰金版500ml | E86: 500ml*6 | F86: 瓶 | G86: 101010544 | H86: 259 | I86: 2046.18 | J86: 529961 | K86: 482679.05 | L86: 47281.95 | M86: 0.0892 | N86: 48 | O86: 25
B87: 白酒 | C87: 白酒-浓香型 | D87: 46°赊店老酒明青花500ml | E87: 500ml*6 | F87: 瓶 | G87: 101010129 | H87: 5536 | I87: 95.72 | J87: 529883.6 | K87: 410560.82 | L87: 119322.78 | M87: 0.2251 | N87: 2778 | O87: 139
B88: 白酒 | C88: 白酒-浓香型 | D88: 52°牛栏山百年陈酿400ml | E88: 400ml*6 | F88: 瓶 | G88: 101010155 | H88: 3709 | I88: 142.48 | J88: 528457.2 | K88: 339330.69 | L88: 189126.51 | M88: 0.3578 | N88: 1801 | O88: 104
B89: 白酒 | C89: 白酒-浓酱兼香型 | D89: 50°白云边五星陈酿500ml | E89: 500ml*6 | F89: 瓶 | G89: 101010139 | H89: 3711 | I89: 135.71 | J89: 503631 | K89: 367438.21 | L89: 136192.79 | M89: 0.2704 | N89: 1831 | O89: 127
B90: 白酒 | C90: 白酒-浓香型 | D90: 52°五粮液戊戌（狗）年生肖纪念酒礼盒 | E90: 500ml*4*1 | F90: 盒 | G90: 101010513 | H90: 406 | I90: 1235.67 | J90: 501682 | K90: 299741.42 | L90: 201940.58 | M90: 0.4025 | N90: 299 | O90: 91
... B131: 白酒 | C131: 白酒-浓酱兼香型 | D131: 45°小郎酒100ml | E131: 100ml*24 | F131: 瓶 | G131: 101010612 | H131: 11313 | I131: 19.79 | J131: 223923.92 | K131: 153561.6 | L131: 70362.323 | M131: 0.3142 | N131: 3520 | O131: 125
B132: 白酒 | C132: 白酒-酱香型 | D132: *53°茅台王子酒（黑金）500ml | F132: 瓶 | G132: 101010568 | H132: 1193 | I132: 186.48 | J132: 222474 | K132: 166013.15 | L132: 56460.846 | M132: 0.2537 | N132: 534 | O132: 84
B133: 白酒 | C133: 白酒-清香型 | D133: 56°炸弹二锅头100ml | E133: 100ml*20 | F133: 瓶 | G133: 101010122 | H133: 33282 | I133: 6.53 | J133: 217248.91 | K133: 129167.7 | L133: 88081.206 | M133: 0.4054 | N133: 6327 | O133: 139
B134: 白酒 | C134: 白酒-浓香型 | D134: 50°五粮醇红淡雅500ml | E134: 500ml*6 | F134: 瓶 | G134: 101010108 | H134: 2900 | I134: 74.41 | J134: 215795 | K134: 173662.77 | L134: 42132.227 | M134: 0.1952 | N134: 1398 | O134: 129
B135: 白酒 | C135: 白酒-清香型 | D135: *43°红星蓝界酒500ml | E135: 500ml*12 | F135: 瓶 | G135: 101010601 | H135: 3188 | I135: 67.46 | J135: 215076 | K135: 124018.98 | L135: 91057.018 | M135: 0.4233 | N135: 1946 | O135: 131
B136: 白酒 | C136: 白酒-酱香型 | D136: 53°老珍酒500ml | E136: 500ml*6 | F136: 瓶 | G136: 101010558 | H136: 2087 | I136: 95.57 | J136: 199453 | K136: 125551.2 | L136: 73901.803 | M136: 0.3705 | N136: 1063 | O136: 75
B137: 白酒 | C137: 白酒其它 | D137: 45°竹叶青酒牧童475ml | E137: 475ml*6 | F137: 瓶 | G137: 101010618 | H137: 3679 | I137: 52.11 | J137: 191702 | K137: 139707.41 | L137: 51994.594 | M137: 0.2712 | N137: 2266 | O137: 134
B138: 白酒 | C138: 白酒-浓香型 | D138: 52°五粮特曲500ml | E138: 500ml*6 | F138: 瓶 | G138: 101010147 | H138: 1005 | I138: 187.38 | J138: 188318 | K138: 142333.74 | L138: 45984.26 | M138: 0.2441 | N138: 327 | O138: 92
B139: 白酒 | C139: 白酒-浓香型 | D139: 52°国窖1573曾娜大师鉴藏版500ml | F139: 瓶 | G139: 101010512 | H139: 200 | I139: 928.26 | J139: 185652 | K139: 148267.13 | L139: 37384.871 | M139: 0.2013 | N139: 29 | O139: 13
B140: 白酒 | C140: 白酒-清香型 | D140: 45°杏花村福酒五(225ml*2) | E140: 225ml*2*6 | F140: 盒 | G140: 101010072 | H140: 3082 | I140: 57.6 | J140: 177538 | K140: 107619.47 | L140: 69918.534 | M140: 0.3938 | N140: 2006 | O140: 132
B141: 白酒 | C141: 白酒-浓香型 | D141: 42°百泉春特制珍品长寿酒500ml | E141: 500ml*4 | F141: 瓶 | G141: 101010181 | H141: 1910 | I141: 84.96 | J141: 162270 | K141: 139822.62 | L141: 22447.38 | M141: 0.1383 | N141: 821 | O141: 9
B142: 白酒 | C142: 白酒-清香型 | D142: 50°汾阳王20年500ml | E142: 500ml*6 | F142: 瓶 | G142: 101010606 | H142: 1002 | I142: 159.65 | J142: 159965 | K142: 71585.4 | L142: 88379.6 | M142: 0.5524 | N142: 324 | O142: 90
...

Sheet 北京
B2: 商品大类 | C2: 商品类别 | D2: 商品名称 | E2: 规格 | F2: 单位 | G2: 商品编码 | H2: 数量 | I2: 成交均价 | J2: 销售额 | K2: 成本 | L2: 毛利 | M2: 毛利率 | N2: 单品客流量 | O2: 销售门店数
H3: 507761 | I3: 222.73173 | J3: 1.1309449e+08 | K3: 95648860 | L3: 17445628 | O3: 11114
B4: 白酒 | C4: 白酒-酱香型 | D4: 53°飞天茅台酒500ml | E4: 500ml*6 | F4: 瓶 | G4: 101010185 | H4: 17566 | I4: 1487.71 | J4: 26133088 | K4: 24438514 | L4: 1694574.3 | M4: 0.0648 | N4: 4039 | O4: 69
B5: 白酒 | C5: 白酒-浓香型 | D5: 52°五粮液普装500ml | E5: 500ml*6 | F5: 瓶 | G5: 101010001 | H5: 10465 | I5: 920.84 | J5: 9636620 | K5: 8425480.9 | L5: 1211139.1 | M5: 0.1256 | N5: 3262 | O5: 81
B6: 白酒 | C6: 白酒-浓香型 | D6: 52°国窖1573 500ml | E6: 500ml*6 | F6: 瓶 | G6: 101010099 | H6: 6344 | I6: 824.19 | J6: 5228661 | K6: 4639409.3 | L6: 589251.69 | M6: 0.1126 | N6: 1714 | O6: 79
B7: 白酒 | C7: 白酒-浓香型 | D7: 52°牛栏山百年陈酿400ml | E7: 400ml*6 | F7: 瓶 | G7: 101010282 | H7: 42416 | I7: 104.26 | J7: 4422122 | K7: 3807479.9 | L7: 614642.06 | M7: 0.1389 | N7: 14594 | O7: 84
B8: 白酒 | C8: 白酒-浓香型 | D8: 36°牛栏山百年陈酿400ml | E8: 400ml*6 | F8: 瓶 | G8: 101010277 | H8: 36043 | I8: 97.14 | J8: 3501051 | K8: 3125683.7 | L8: 375367.27 | M8: 0.1072 | N8: 12034 | O8: 84
B9: 白酒 | C9: 白酒-浓香型 | D9: 52°五粮液1618 500ml | E9: 500ml*6 | F9: 瓶 | G9: 101010139 | H9: 3675 | I9: 918.27 | J9: 3374659 | K9: 2917462.7 | L9: 457196.34 | M9: 0.1354 | N9: 1245 | O9: 78
B10: 白酒 | C10: 白酒-浓香型 | D10: 52°剑南春普装500ml | E10: 500ml*6 | F10: 瓶 | G10: 101010002 | H10: 8040 | I10: 405.69 | J10: 3261717 | K10: 2752154.3 | L10: 509562.7 | M10: 0.1562 | N10: 3024 | O10: 81
B11: 白酒 | C11: 白酒-清香型 | D11: 52°牛栏山经典二锅头500ml | E11: 500ml*6 | F11: 瓶 | G11: 101010281 | H11: 7499 | I11: 389.57 | J11: 2921388 | K11: 2362765.7 | L11: 558622.33 | M11: 0.1912 | N11: 2313 | O11: 78
B12: 白酒 | C12: 白酒-清香型 | D12: 53°牛栏山三十年珍品二锅头500ml | E12: 500ml*6 | F12: 瓶 | G12: 101010278 | H12: 11702 | I12: 176.32 | J12: 2063246.8 | K12: 1847811 | L12: 215435.77 | M12: 0.1044 | N12: 4095 | O12: 79
B13: 白酒 | C13: 白酒-清香型 | D13: 53°汾酒20年青花500ml | E13: 500ml*6 | F13: 瓶 | G13: 101010192 | H13: 4773 | I13: 414.55 | J13: 1978671 | K13: 1656455.4 | L13: 322215.64 | M13: 0.1628 | N13: 1598 | O13: 80
B14: 白酒 | C14: 白酒-酱香型 | D14: 43°飞天茅台500ml | E14: 500ml*6 | F14: 瓶 | G14: 101010290 | H14: 2021 | I14: 939.09 | J14: 1897902 | K14: 1368711.4 | L14: 529190.59 | M14: 0.2788 | N14: 896 | O14: 72
B15: 白酒 | C15: 白酒-酱香型 | D15: 53°飞天茅台酒1L | E15: 1L*12 | F15: 瓶 | G15: 101020029 | H15: 480 | I15: 3950.84 | J15: 1896404 | K15: 1754282.4 | L15: 142121.61 | M15: 0.0749 | N15: 292 | O15: 51
... B45: 白酒 | C45: 白酒-浓香型 | D45: 52°泸州老窖特曲500ml | E45: 500ml*6 | F45: 瓶 | G45: 101010036 | H45: 2387 | I45: 210.81 | J45: 503192 | K45: 367065.15 | L45: 136126.85 | M45: 0.2705 | N45: 986 | O45: 76
B46: 白酒 | C46: 白酒-清香型 | D46: 43°红星蓝瓶八年陈酿750ml | F46: 瓶 | G46: 101030004 | H46: 13968 | I46: 35.42 | J46: 494797.5 | K46: 406611.46 | L46: 88186.044 | M46: 0.1782 | N46: 7839 | O46: 83
B47: 白酒 | C47: 白酒-浓香型 | D47: 52°小糊涂仙500ml | E47: 500ml*12 | F47: 瓶 | G47: 101010096 | H47: 2814 | I47: 165.53 | J47: 465808 | K47: 340599.48 | L47: 125208.52 | M47: 0.2687 | N47: 1502 | O47: 80
B48: 白酒 | C48: 白酒-浓香型 | D48: 38°剑南春500ml | E48: 500ml*6 | F48: 瓶 | G48: 101010306 | H48: 1195 | I48: 386.31 | J48: 461646 | K48: 345982.93 | L48: 115663.07 | M48: 0.2505 | N48: 452 | O48: 64
B49: 白酒 | C49: 白酒-浓香型 | D49: 39°五粮液1618 500ml | E49: 500ml*6 | F49: 瓶 | G49: 101010260 | H49: 685 | I49: 670.24 | J49: 459112 | K49: 352967.31 | L49: 106144.69 | M49: 0.2311 | N49: 239 | O49: 61
B50: 白酒 | C50: 白酒-清香型 | D50: 43°红星蓝瓶八年陈酿500ml | E50: 500ml*12 | F50: 瓶 | G50: 101010309 | H50: 16756 | I50: 25.36 | J50: 424880.4 | K50: 352161.96 | L50: 72718.442 | M50: 0.1711 | N50: 8667 | O50: 83
B51: 白酒 | C51: 白酒-酱香型 | D51: 53°习酒窖藏1988 500ml | E51: 500ml*6 | F51: 瓶 | G51: 101020053 | H51: 632 | I51: 639.18 | J51: 403964 | K51: 327866.02 | L51: 76097.977 | M51: 0.1883 | N51: 223 | O51: 60
B52: 白酒 | C52: 白酒-清香型 | D52: 53°老白汾酒封坛拾伍年475ml | E52: 475ml*6 | F52: 瓶 | G52: 101010113 | H52: 2093 | I52: 190.43 | J52: 398564 | K52: 277576.28 | L52: 120987.72 | M52: 0.3035 | N52: 967 | O52: 74
B53: 白酒 | C53: 白酒-浓香型 | D53: 52°舍得酒500ml（BJ） | E53: 500ml*6 | F53: 瓶 | G53: 101010263 | H53: 906 | I53: 411.83 | J53: 373120 | K53: 311003.71 | L53: 62116.289 | M53: 0.1664 | N53: 357 | O53: 63
B54: 白酒 | C54: 白酒-酱香型 | D54: 53°习酒银质500ml | E54: 500ml*6 | F54: 瓶 | G54: 101020010 | H54: 2516 | I54: 144.42 | J54: 363351 | K54: 242153.51 | L54: 121197.49 | M54: 0.3335 | N54: 1242 | O54: 78
B55: 白酒 | C55: 白酒其它 | D55: 40°江小白300ml | E55: 300ml*12 | F55: 瓶 | G55: 101990010 | H55: 8427 | I55: 42.55 | J55: 358594.3 | K55: 270239.72 | L55: 88354.579 | M55: 0.2463 | N55: 4306 | O55: 81
B56: 白酒 | C56: 白酒-清香型 | D56: 霸王醉典藏礼盒250ml*2 | E56: 250ml*2*5 | F56: 瓶 | G56: 101030026 | H56: 345 | I56: 1030.69 | J56: 355588 | K56: 326726.92 | L56: 28861.078 | M56: 0.0811 | N56: 29 | O56: 12
B57: 白酒 | C57: 白酒-酱香型 | D57: 53°茅台王子酒500ml | E57: 500ml*6 | F57: 瓶 | G57: 101010107 | H57: 2428 | I57: 143.79 | J57: 349122 | K57: 247993.97 | L57: 101128.03 | M57: 0.2896 | N57: 1320 | O57: 80
B58: 白酒 | C58: 白酒-浓香型 | D58: 38°牛栏山百年红十年500ml | E58: 500ml*6 | F58: 瓶 | G58: 101010272 | H58: 4710 | I58: 71.63 | J58: 337386 | K58: 310534.26 | L58: 26851.743 | M58: 0.0795 | N58: 1627 | O58: 80
... B62: 白酒 | C62: 白酒-清香型 | D62: 52°红星青花瓷珍品二锅头750ml | E62: 750ml*6 | F62: 瓶 | G62: 101010321 | H62: 1070 | I62: 281.96 | J62: 301695 | K62: 206347.77 | L62: 95347.234 | M62: 0.316 | N62: 506 | O62: 70
B63: 白酒 | C63: 白酒-酱香型 | D63: 53°飞天茅台狗年500ml | F63: 瓶 | G63: 101020101 | H63: 66 | I63: 4533.18 | J63: 299190 | K63: 266535.84 | L63: 32654.16 | M63: 0.1091 | N63: 29 | O63: 12
B64: 白酒 | C64: 白酒-清香型 | D64: 53°汾酒紫砂陶475ml | E64: 475ml*6 | F64: 瓶 | G64: 101010070 | H64: 2945 | I64: 98.27 | J64: 289394 | K64: 196298.74 | L64: 93095.257 | M64: 0.3216 | N64: 1452 | O64: 81
B65: 白酒 | C65: 白酒-酱香型 | D65: 53°赖茅重沙500ml | F65: 瓶 | G65: 101020056 | H65: 1107 | I65: 255.41 | J65: 282740 | K65: 170772.9 | L65: 111967.1 | M65: 0.396 | N65: 484 | O65: 68
B66: 白酒 | C66: 白酒-清香型 | D66: 45°牛栏山珍品二锅头400ml | E66: 400ml*6 | F66: 瓶 | G66: 101010270 | H66: 6086 | I66: 44.98 | J66: 273753.86 | K66: 221954.55 | L66: 51799.31 | M66: 0.1892 | N66: 2291 | O66: 82
B67: 白酒 | C67: 白酒-浓香型 | D67: 52°泸州窖酒陶坛老酒500ml | E67: 500ml*6 | F67: 瓶 | G67: 101010421 | H67: 1579 | I67: 168 | J67: 265272 | K67: 141815.9 | L67: 123456.1 | M67: 0.4653 | N67: 994 | O67: 77
B68: 白酒 | C68: 白酒-清香型 | D68: 53°清香至尊蓝瓷汾酒475ml | E68: 475ml*6 | F68: 瓶 | G68: 101010337 | H68: 2238 | I68: 118.02 | J68: 264124 | K68: 186458.82 | L68: 77665.176 | M68: 0.294 | N68: 983 | O68: 73
B69: 白酒 | C69: 白酒-清香型 | D69: 53°汾酒475ml | E69: 475ml*12 | F69: 瓶 | G69: 999010016 | H69: 5493 | I69: 45.84 | J69: 251803 | K69: 159221.39 | L69: 92581.608 | M69: 0.3676 | N69: 2979 | O69: 78
B70: 白酒 | C70: 白酒-清香型 | D70: 46°北京二锅头酒（土豪金版）500ml | E70: 500ml*6 | F70: 瓶 | G70: 101030043 | H70: 2246 | I70: 111.99 | J70: 251530 | K70: 131114.19 | L70: 120415.81 | M70: 0.4787 | N70: 1069 | O70: 77
B71: 白酒 | C71: 白酒其它 | D71: 52°洋河梦之蓝M6 500ml | E71: 500ml*4 | F71: 瓶 | G71: 101010193 | H71: 370 | I71: 666.83 | J71: 246726 | K71: 216540.35 | L71: 30185.647 | M71: 0.1223 | N71: 142 | O71: 53
B72: 白酒 | C72: 白酒-浓香型 | D72: 52°百年泸州老窖酒窖龄30年500ml | E72: 500ml*6 | F72: 瓶 | G72: 101010114 | H72: 1087 | I72: 224.39 | J72: 243910 | K72: 175117.95 | L72: 68792.053 | M72: 0.282 | N72: 378 | O72: 71
B73: 白酒 | C73: 白酒-酱香型 | D73: 53°飞天茅台酒1.3L | E73: 1.3L*4 | F73: 瓶 | G73: 101020048 | H73: 46 | I73: 4789 | J73: 220294 | K73: 160981.6 | L73: 59312.4 | M73: 0.2692 | N73: 33 | O73: 14
...

Sheet 西安
B2: 商品大类 | C2: 商品类别 | D2: 商品名称 | E2: 规格 | F2: 单位 | G2: 商品编码 | H2: 数量 | I2: 成交均价 | J2: 销售额 | K2: 成本 | L2: 毛利 | M2: 毛利率 | N2: 单品客流量 | O2: 销售门店数
H3: 103663 | I3: 312.32229 | J3: 32376266 | K3: 27803838 | L3: 4572427.9 | O3: 2541
B4: 白酒 | C4: 白酒-酱香型 | D4: 53°飞天茅台酒500ml | E4: 500ml*6 | F4: 瓶 | G4: 101010185 | H4: 4585 | I4: 1490.77 | J4: 6835178 | K4: 6275580.8 | L4: 559597.24 | M4: 0.0818 | N4: 883 | O4: 22
B5: 白酒 | C5: 白酒-浓香型 | D5: 52°五粮液普装500ml | E5: 500ml*6 | F5: 瓶 | G5: 101010001 | H5: 4867 | I5: 886.5 | J5: 4314601 | K5: 3956015 | L5: 358585.97 | M5: 0.0831 | N5: 1564 | O5: 23
B6: 白酒 | C6: 白酒-浓香型 | D6: 52°国窖1573 500ml | E6: 500ml*6 | F6: 瓶 | G6: 101010099 | H6: 3221 | I6: 822.69 | J6: 2649887 | K6: 2326537.4 | L6: 323349.59 | M6: 0.122 | N6: 813 | O6: 23
B7: 白酒 | C7: 白酒-酱香型 | D7: 53°茅台酒15年500ml礼盒装 | E7: 500ml*6 | F7: 盒 | G7: 101020023 | H7: 362 | I7: 5086.27 | J7: 1841228 | K7: 1708407 | L7: 132820.96 | M7: 0.0721 | N7: 158 | O7: 19
B8: 白酒 | C8: 白酒-凤香型 | D8: 45°西凤6年陈酿500ml | E8: 500ml*6 | F8: 瓶 | G8: 101010476 | H8: 10884 | I8: 149.99 | J8: 1632500 | K8: 1414734.2 | L8: 217765.81 | M8: 0.1333 | N8: 4633 | O8: 22
B9: 白酒 | C9: 白酒-浓香型 | D9: 52°剑南春普装500ml | E9: 500ml*6 | F9: 瓶 | G9: 101010002 | H9: 3614 | I9: 382.5 | J9: 1382338 | K9: 1244022.2 | L9: 138315.84 | M9: 0.1 | N9: 1290 | O9: 23
B10: 白酒 | C10: 白酒-浓香型 | D10: 52°五粮液1618 500ml | E10: 500ml*6 | F10: 瓶 | G10: 101010139 | H10: 1369 | I10: 907.65 | J10: 1242571 | K10: 1090896.9 | L10: 151674.11 | M10: 0.122 | N10: 451 | O10: 22
B11: 白酒 | C11: 白酒-凤香型 | D11: 45°西凤华山论剑20年500ml | E11: 500ml*6 | F11: 瓶 | G11: 101010479 | H11: 4160 | I11: 243.2 | J11: 1011722 | K11: 872179.06 | L11: 139542.94 | M11: 0.1379 | N11: 1621 | O11: 22
B12: 白酒 | C12: 白酒-酱香型 | D12: 43°飞天茅台500ml | E12: 500ml*6 | F12: 瓶 | G12: 101010290 | H12: 1148 | I12: 878.2 | J12: 1008170 | K12: 793903.26 | L12: 214266.74 | M12: 0.2125 | N12: 193 | O12: 22
B13: 白酒 | C13: 白酒-凤香型 | D13: 45°西凤华山论剑10年500ml | E13: 500ml*6 | F13: 瓶 | G13: 101010478 | H13: 4015 | I13: 137.13 | J13: 550559 | K13: 440800.04 | L13: 109758.96 | M13: 0.1993 | N13: 1902 | O13: 22
B14: 白酒 | C14: 白酒-酱香型 | D14: *53°飞天茅台三十年500ml | E14: 500ml*6 | F14: 瓶 | G14: 101010289 | H14: 48 | I14: 11363.58 | J14: 545452 | K14: 470665.74 | L14: 74786.263 | M14: 0.1371 | N14: 18 | O14: 8
B15: 白酒 | C15: 白酒-酱香型 | D15: 53°飞天茅台酒375ml | E15: 375ml*12 | F15: 瓶 | G15: 101020107 | H15: 360 | I15: 1499 | J15: 539640 | K15: 476400 | L15: 63240 | M15: 0.1171 | N15: 64 | O15: 14
... B23: 白酒 | C23: 白酒-浓香型 | D23: 52°百年泸州老窖酒窖龄60年500ml | E23: 500ml*6 | F23: 瓶 | G23: 101010115 | H23: 876 | I23: 273.45 | J23: 239538 | K23: 160260.37 | L23: 79277.631 | M23: 0.3309 | N23: 334 | O23: 21
B24: 白酒 | C24: 白酒-酱香型 | D24: 53°飞天茅台狗年500ml | F24: 瓶 | G24: 101020101 | H24: 54 | I24: 4377.78 | J24: 236400 | K24: 210870 | L24: 25530 | M24: 0.1079 | N24: 13 | O24: 3
B25: 白酒 | C25: 白酒-酱香型 | D25: 53°飞天茅台酒200ml | E25: 200ml*12 | F25: 瓶 | G25: 101020108 | H25: 211 | I25: 837.35 | J25: 176681 | K25: 158250 | L25: 18431 | M25: 0.1043 | N25: 51 | O25: 15
B26: 白酒 | C26: 白酒-凤香型 | D26: 55°西凤酒红西风500ml | E26: 500ml*4 | F26: 瓶 | G26: 101010483 | H26: 315 | I26: 557.75 | J26: 175692 | K26: 139395.06 | L26: 36296.935 | M26: 0.2065 | N26: 111 | O26: 19
B27: 白酒 | C27: 白酒-酱香型 | D27: 53°贵州茅台酒（澳门回归18年纪念）5L | E27: 5L*1 | F27: 盒 | G27: 101020131 | H27: 5 | I27: 35000 | J27: 175000 | K27: 165400 | L27: 9600 | M27: 0.0548 | N27: 1 | O27: 1
B28: 白酒 | C28: 白酒-酱香型 | D28: 53°贵州茅台酒（澳门回归18年纪念）陈酿5L | E28: 5L*1 | F28: 盒 | G28: 101020132 | H28: 5 | I28: 35000 | J28: 175000 | K28: 165400 | L28: 9600 | M28: 0.0548 | N28: 1 | O28: 1
B29: 白酒 | C29: 白酒-浓香型 | D29: 52°水井坊井台装500ml | E29: 500ml*6 | F29: 瓶 | G29: 101010006 | H29: 358 | I29: 476.06 | J29: 170431 | K29: 142265.95 | L29: 28165.048 | M29: 0.1652 | N29: 151 | O29: 19
B30: 白酒 | C30: 白酒-清香型 | D30: 53°汾酒475ml | E30: 475ml*12 | F30: 瓶 | G30: 999010016 | H30: 3853 | I30: 43.82 | J30: 168856 | K30: 122094.69 | L30: 46761.314 | M30: 0.2769 | N30: 2158 | O30: 22
B31: 白酒 | C31: 白酒-浓香型 | D31: *46°洋河海之蓝480ml | E31: 480ml*6 | F31: 瓶 | G31: 101010003 | H31: 1203 | I31: 137.59 | J31: 165526 | K31: 138198.05 | L31: 27327.95 | M31: 0.165 | N31: 600 | O31: 22
B32: 白酒 | C32: 白酒其它 | D32: 52°洋河梦之蓝M3 500ml | E32: 500ml*4 | F32: 瓶 | G32: 101010119 | H32: 285 | I32: 574.19 | J32: 163643 | K32: 112561.12 | L32: 51081.876 | M32: 0.3121 | N32: 125 | O32: 21
B33: 白酒 | C33: 白酒-清香型 | D33: 53°汾酒20年青花500ml | E33: 500ml*6 | F33: 瓶 | G33: 101010192 | H33: 395 | I33: 388.87 | J33: 153604 | K33: 143385.55 | L33: 10218.448 | M33: 0.0665 | N33: 155 | O33: 22
B34: 白酒 | C34: 白酒-浓香型 | D34: 52°百年泸州老窖酒窖龄30年500ml | E34: 500ml*6 | F34: 瓶 | G34: 101010114 | H34: 648 | I34: 204.38 | J34: 132441 | K34: 99922.282 | L34: 32518.718 | M34: 0.2455 | N34: 244 | O34: 22
B35: 白酒 | C35: 白酒-清香型 | D35: 53°老白汾酒封坛拾伍年475ml | E35: 475ml*6 | F35: 瓶 | G35: 101010113 | H35: 526 | I35: 232.56 | J35: 122329 | K35: 82412.19 | L35: 39916.81 | M35: 0.3263 | N35: 263 | O35: 22
B36: 白酒 | C36: 白酒-酱香型 | D36: 53°红花郎15年500ml | E36: 500ml*6 | F36: 瓶 | G36: 101010140 | H36: 230 | I36: 529.95 | J36: 121888 | K36: 100642.71 | L36: 21245.29 | M36: 0.1743 | N36: 85 | O36: 18
... B53: 白酒 | C53: 白酒-清香型 | D53: *52°汾酒清香酒海475ml | E53: 475ml*6 | F53: 瓶 | G53: 101030015 | H53: 1356 | I53: 61.27 | J53: 83078 | K53: 57501.57 | L53: 25576.43 | M53: 0.3078 | N53: 253 | O53: 20
B54: 白酒 | C54: 白酒-酱香型 | D54: 53°赖茅重沙500ml | F54: 瓶 | G54: 101020056 | H54: 286 | I54: 285.67 | J54: 81702 | K54: 44128.631 | L54: 37573.369 | M54: 0.4598 | N54: 165 | O54: 22
B55: 白酒 | C55: 白酒-凤香型 | D55: 45°西凤酒375ml | E55: 375ml*20 | F55: 瓶 | G55: 101010484 | H55: 3216 | I55: 24.26 | J55: 78035.5 | K55: 65398.249 | L55: 12637.251 | M55: 0.1619 | N55: 1462 | O55: 22
B56: 白酒 | C56: 白酒-浓香型 | D56: 52°泸州老窖头曲500ml | E56: 500ml*6 | F56: 瓶 | G56: 101010024 | H56: 1433 | I56: 54.37 | J56: 77914 | K56: 54113.372 | L56: 23800.627 | M56: 0.3054 | N56: 785 | O56: 22
B57: 白酒 | C57: 白酒-酱香型 | D57: 53°习酒红盒 500ml | E57: 500ml*6 | F57: 瓶 | G57: 101020006 | H57: 890 | I57: 80.57 | J57: 71706 | K57: 47100.45 | L57: 24605.55 | M57: 0.3431 | N57: 486 | O57: 22
B58: 白酒 | C58: 白酒-浓香型 | D58: 52°五粮液E60珍品酒 500ml | E58: 500ml*6 | F58: 瓶 | G58: 101020062 | H58: 744 | I58: 96.36 | J58: 71694 | K58: 40259.061 | L58: 31434.939 | M58: 0.4384 | N58: 197 | O58: 21
B59: 白酒 | C59: 白酒-浓香型 | D59: 52°五粮液(交杯牌)500ml | E59: 500ml*6 | F59: 瓶 | G59: 101010492 | H59: 58 | I59: 1154.55 | J59: 66964 | K59: 51379.779 | L59: 15584.221 | M59: 0.2327 | N59: 24 | O59: 12
B60: 白酒 | C60: 白酒-酱香型 | D60: 53°茅台迎宾酒500ml | E60: 500ml*6 | F60: 瓶 | G60: 101010217 | H60: 870 | I60: 73.87 | J60: 64271 | K60: 54674.4 | L60: 9596.6002 | M60: 0.1493 | N60: 376 | O60: 22
B61: 白酒 | C61: 白酒其它 | D61: 40°江小白100ml | E61: 100ml*24 | F61: 瓶 | G61: 101990007 | H61: 3439 | I61: 17.74 | J61: 61018 | K61: 39648.262 | L61: 21369.738 | M61: 0.3502 | N61: 1161 | O61: 22
B62: 白酒 | C62: 白酒-浓香型 | D62: *52°五粮液虎符令酒500ml | E62: 500ml*6 | F62: 瓶 | G62: 101010530 | H62: 54 | I62: 1075.41 | J62: 58072 | K62: 47597.23 | L62: 10474.77 | M62: 0.1803 | N62: 22 | O62: 14
B63: 白酒 | C63: 白酒-清香型 | D63: 53°汾酒紫砂陶475ml | E63: 475ml*6 | F63: 瓶 | G63: 101010070 | H63: 583 | I63: 96.95 | J63: 56519 | K63: 42417.994 | L63: 14101.006 | M63: 0.2494 | N63: 340 | O63: 22
B64: 白酒 | C64: 白酒-浓香型 | D64: 52°五粮液六和液盛典装500ml | E64: 500ml*6 | F64: 瓶 | G64: 101010138 | H64: 400 | I64: 139.88 | J64: 55952 | K64: 43701.39 | L64: 12250.61 | M64: 0.2189 | N64: 121 | O64: 22
...

Sheet 徐州
B2: 商品大类 | C2: 商品类别 | D2: 商品名称 | E2: 规格 | F2: 单位 | G2: 商品编码 | H2: 数量 | I2: 成交均价 | J2: 销售额 | K2: 成本 | L2: 毛利 | M2: 毛利率 | N2: 单品客流量 | O2: 销售门店数
H3: 27695 | I3: 159.6969 | J3: 4422805.6 | K3: 3871153.2 | L3: 551652.45 | O3: 755
B4: 白酒 | C4: 白酒-酱香型 | D4: 53°飞天茅台酒500ml | E4: 500ml*6 | F4: 瓶 | G4: 101010185 | H4: 750 | I4: 1535.8 | J4: 1151853 | K4: 1031076.1 | L4: 120776.91 | M4: 0.1048 | N4: 157 | O4: 8
B5: 白酒 | C5: 白酒-浓香型 | D5: 42°洋河蓝色经典海之蓝480ml | E5: 480ml*6 | F5: 瓶 | G5: 101010255 | H5: 3615 | I5: 121.45 | J5: 439031 | K5: 418252.33 | L5: 20778.669 | M5: 0.0473 | N5: 1126 | O5: 12
B6: 白酒 | C6: 白酒-浓香型 | D6: 52°五粮液普装500ml | E6: 500ml*6 | F6: 瓶 | G6: 101010001 | H6: 470 | I6: 867.72 | J6: 407828 | K6: 384679.32 | L6: 23148.684 | M6: 0.0567 | N6: 85 | O6: 9
B7: 白酒 | C7: 白酒 | D7: 42°国缘对开500ml | E7: 500ml*6 | F7: 瓶 | G7: 101020077 | H7: 762 | I7: 282.6 | J7: 215344 | K7: 198183.07 | L7: 17160.933 | M7: 0.0796 | N7: 222 | O7: 9
B8: 白酒 | C8: 白酒-浓香型 | D8: 42°洋河天之蓝480ml | F8: 瓶 | G8: 101020074 | H8: 613 | I8: 289.37 | J8: 177384 | K8: 167278.17 | L8: 10105.834 | M8: 0.0569 | N8: 178 | O8: 11
B9: 白酒 | C9: 白酒-浓香型 | D9: 52°五粮液1618 500ml | E9: 500ml*6 | F9: 瓶 | G9: 101010139 | H9: 179 | I9: 869.92 | J9: 155715 | K9: 145405.28 | L9: 10309.725 | M9: 0.0662 | N9: 19 | O9: 7
B10: 白酒 | C10: 白酒-浓香型 | D10: 41.8°+68°双沟珍宝坊君坊(480ml+20ml) | F10: 盒 | G10: 101020071 | H10: 1510 | I10: 89.21 | J10: 134708 | K10: 122867.24 | L10: 11840.765 | M10: 0.0878 | N10: 443 | O10: 12
B11: 白酒 | C11: 白酒-浓香型 | D11: 40.8°洋河梦之蓝M3 500ml | F11: 瓶 | G11: 101020073 | H11: 330 | I11: 393.72 | J11: 129929 | K11: 122972.21 | L11: 6956.7893 | M11: 0.0535 | N11: 105 | O11: 9
B12: 白酒 | C12: 白酒-浓香型 | D12: 52°水井坊臻酿八号500ml | E12: 500ml*6 | F12: 瓶 | G12: 101010495 | H12: 311 | I12: 317.11 | J12: 98621 | K12: 83322.827 | L12: 15298.173 | M12: 0.1551 | N12: 48 | O12: 8
B13: 白酒 | C13: 白酒-浓香型 | D13: 52°国窖1573 500ml | E13: 500ml*6 | F13: 瓶 | G13: 101010099 | H13: 113 | I13: 831.88 | J13: 94002 | K13: 83302.9 | L13: 10699.1 | M13: 0.1138 | N13: 19 | O13: 7
B14: 白酒 | C14: 白酒 | D14: 42°国缘四开500ml | F14: 瓶 | G14: 101020072 | H14: 216 | I14: 416.53 | J14: 89970 | K14: 83118.75 | L14: 6851.2505 | M14: 0.0761 | N14: 56 | O14: 8
B15: 白酒 | C15: 白酒-浓香型 | D15: 45°五粮春500ml | E15: 500ml*12 | F15: 瓶 | G15: 101010259 | H15: 499 | I15: 168 | J15: 83832 | K15: 78404.461 | L15: 5427.5395 | M15: 0.0647 | N15: 191 | O15: 11
B16: 白酒 | C16: 白酒其它 | D16: 40.8°洋河梦之蓝M6 500ml | E16: 500ml*6 | F16: 瓶 | G16: 101990013 | H16: 149 | I16: 523.97 | J16: 78071 | K16: 72504.49 | L16: 5566.5096 | M16: 0.0713 | N16: 45 | O16: 9
B17: 白酒 | C17: 白酒-清香型 | D17: 42°汾阳王10年500ml | E17: 500ml*6 | F17: 瓶 | G17: 101030021 | H17: 2162 | I17: 34.89 | J17: 75435 | K17: 54050 | L17: 21385 | M17: 0.2834 | N17: 512 | O17: 12
B18: 白酒 | C18: 白酒-浓香型 | D18: 52°剑南春普装500ml | E18: 500ml*6 | F18: 瓶 | G18: 101010002 | H18: 167 | I18: 387.87 | J18: 64774 | K18: 57323.026 | L18: 7450.9735 | M18: 0.115 | N18: 43 | O18: 6
B19: 白酒 | C19: 白酒-浓香型 | D19: 42°百年迎驾贡典藏450ml | E19: 450ml*4 | F19: 瓶 | G19: 101020083 | H19: 842 | I19: 63.07 | J19: 53108 | K19: 43660.386 | L19: 9447.6138 | M19: 0.1778 | N19: 335 | O19: 10
B20: 白酒 | C20: 白酒-酱香型 | D20: 40.8°口子窖五年400ml | E20: 400ml *6 | F20: 瓶 | G20: 101010299 | H20: 501 | I20: 90.38 | J20: 45282 | K20: 40536.327 | L20: 4745.673 | M20: 0.1048 | N20: 221 | O20: 10
B21: 白酒 | C21: 白酒-浓香型 | D21: 42°今世缘典藏10年500ml | F21: 瓶 | G21: 101020075 | H21: 447 | I21: 93.09 | J21: 41612 | K21: 37700.479 | L21: 3911.5206 | M21: 0.0939 | N21: 72 | O21: 8
B22: 白酒 | C22: 白酒-浓香型 | D22: 42°国缘淡雅500ml | E22: 500ml*6 | F22: 瓶 | G22: 101020128 | H22: 308 | I22: 126.86 | J22: 39072 | K22: 32648 | L22: 6424 | M22: 0.1644 | N22: 115 | O22: 9
B23: 白酒 | C23: 白酒-浓香型 | D23: 42°三星百年迎驾贡450ml | E23: 450ml*6 | F23: 瓶 | G23: 101020082 | H23: 751 | I23: 47.62 | J23: 35762 | K23: 31451.154 | L23: 4310.8458 | M23: 0.1205 | N23: 460 | O23: 11
B24: 白酒 | C24: 白酒-浓香型 | D24: 52°五粮液100年传奇柔和500ml | E24: 500ml*6 | F24: 瓶 | G24: 101010526 | H24: 621 | I24: 55.26 | J24: 34319 | K24: 20613.625 | L24: 13705.376 | M24: 0.3993 | N24: 128 | O24: 11
B25: 白酒 | C25: 白酒-清香型 | D25: 53°汾酒20年青花500ml | E25: 500ml*6 | F25: 瓶 | G25: 101010192 | H25: 88 | I25: 382.73 | J25: 33680 | K25: 30120.068 | L25: 3559.9317 | M25: 0.1056 | N25: 23 | O25: 6
B26: 白酒 | C26: 白酒-浓香型 | D26: 52°水井坊井台装500ml | E26: 500ml*6 | F26: 瓶 | G26: 101010006 | H26: 67 | I26: 473.15 | J26: 31701 | K26: 27749.682 | L26: 3951.3182 | M26: 0.1246 | N26: 16 | O26: 7
B27: 白酒 | C27: 白酒-浓香型 | D27: 52°五粮液戊戌（狗）年生肖纪念酒礼盒 | E27: 500ml*4*1 | F27: 盒 | G27: 101010523 | H27: 29 | I27: 1068.55 | J27: 30988 | K27: 20824.615 | L27: 10163.385 | M27: 0.3279 | N27: 19 | O27: 6
B28: 白酒 | C28: 白酒-浓香型 | D28: 52°泸州窖酒陶坛老酒500ml | E28: 500ml*6 | F28: 瓶 | G28: 101010421 | H28: 199 | I28: 153.23 | J28: 30492 | K28: 17826.923 | L28: 12665.077 | M28: 0.4153 | N28: 109 | O28: 8
B29: 白酒 | C29: 白酒-清香型 | D29: 53°汾酒30年青花500ml | E29: 500ml*6 | F29: 瓶 | G29: 101010068 | H29: 58 | I29: 515.31 | J29: 29888 | K29: 25812.071 | L29: 4075.9293 | M29: 0.1363 | N29: 6 | O29: 3
B30: 白酒 | C30: 白酒-浓香型 | D30: 52°绵竹大曲窖藏500ml | E30: 500ml*6 | F30: 瓶 | G30: 101010456 | H30: 981 | I30: 29.18 | J30: 28623 | K30: 19567.911 | L30: 9055.0895 | M30: 0.3163 | N30: 263 | O30: 10
B31: 白酒 | C31: 白酒-酱香型 | D31: 53°红花郎10年500ml | E31: 500ml*6 | F31: 瓶 | G31: 101010053 | H31: 85 | I31: 332.07 | J31: 28226 | K31: 23162.427 | L31: 5063.5732 | M31: 0.1793 | N31: 25 | O31: 6
B32: 白酒 | C32: 白酒-酱香型 | D32: 43°飞天茅台500ml | E32: 500ml*6 | F32: 瓶 | G32: 101010290 | H32: 28 | I32: 988.5 | J32: 27678 | K32: 18701.569 | L32: 8976.4308 | M32: 0.3243 | N32: 11 | O32: 6
B33: 白酒 | C33: 白酒其它 | D33: *52°酒鬼酒（天工开物/馥郁天成）1L | E33: 1L*6 | F33: 瓶 | G33: 101990008 | H33: 96 | I33: 285.96 | J33: 27452 | K33: 18077.13 | L33: 9374.8699 | M33: 0.3415 | N33: 40 | O33: 9
... B40: 白酒 | C40: 白酒-清香型 | D40: 53°老白汾酒特制十年475ml | E40: 475ml*6 | F40: 瓶 | G40: 101010071 | H40: 128 | I40: 139.06 | J40: 17800 | K40: 14034.308 | L40: 3765.6922 | M40: 0.2115 | N40: 47 | O40: 8
B41: 白酒 | C41: 白酒-浓香型 | D41: 42°习酒虹钻500ml | F41: 瓶 | G41: 101020065 | H41: 157 | I41: 113.34 | J41: 17795 | K41: 10861.368 | L41: 6933.6323 | M41: 0.3896 | N41: 39 | O41: 7
B42: 白酒 | C42: 白酒-浓香型 | D42: 50°五粮醇3D 500ml | E42: 500ml*6 | F42: 瓶 | G42: 101010108 | H42: 379 | I42: 45.92 | J42: 17405 | K42: 14469.806 | L42: 2935.1939 | M42: 0.1686 | N42: 141 | O42: 10
B43: 白酒 | C43: 白酒-清香型 | D43: *52°汾酒清香酒海475ml | E43: 475ml*6 | F43: 瓶 | G43: 101030015 | H43: 235 | I43: 66.94 | J43: 15731 | K43: 10046.935 | L43: 5684.0654 | M43: 0.3613 | N43: 65 | O43: 9
B44: 白酒 | C44: 白酒-浓香型 | D44: 50°五粮春500ml | E44: 500ml*6 | F44: 瓶 | G44: 101010494 | H44: 58 | I44: 214.28 | J44: 12428 | K44: 10490.435 | L44: 1937.5649 | M44: 0.1559 | N44: 25 | O44: 8
B45: 白酒 | C45: 白酒-浓香型 | D45: *52°全兴1963 500ml | E45: 500ml*12 | F45: 瓶 | G45: 101010454 | H45: 303 | I45: 40.63 | J45: 12311 | K45: 7441.693 | L45: 4869.307 | M45: 0.3955 | N45: 130 | O45: 9
B46: 白酒 | C46: 白酒-浓香型 | D46: 42°牛栏山陈酿白酒500ml | E46: 500ml*12 | F46: 瓶 | G46: 101030011 | H46: 926 | I46: 12.89 | J46: 11939.8 | K46: 9712.8327 | L46: 2226.9673 | M46: 0.1865 | N46: 458 | O46: 11
B47: 白酒 | C47: 白酒-浓香型 | D47: 52°舍得酒500ml（HN） | E47: 500ml*6 | F47: 瓶 | G47: 101010019 | H47: 26 | I47: 421.5 | J47: 10959 | K47: 9019.9041 | L47: 1939.0959 | M47: 0.1769 | N47: 12 | O47: 6
...

Sheet 清洗
A1: 序号 | B1: 商品编码 | C1: 商品名称 | D1: 规格 | E1: 单价 | F1: 全年计划总量(瓶) | G1: 全年计划采购总金额 | H1: 成交价 | I1: 出库数量 | J1: 2017.11-2018.10出库金额 | K1: 出库数量 | L1: 2017.5-2017.10出库金额 | M1: 出库数量 | N1: 2018.5-2018.10出库金额 | O1: 地区
A2: 2 | B2: 101010099 | C2: 52°国窖1573 500ml | D2: 500ml*6 | E2: 740 | F2: 15600 | G2: 11544000 | H2: 830.06 | I2: 13122 | J2: 10892047 | K2: 5289 | L2: 4390187.3 | M2: 4995 | N2: 4146149.7 | O2: 河南
A3: 3 | B3: 101010114 | C3: *52°百年泸州老窖酒窖龄30年500ml | D3: 500ml*6 | E3: 165 | F3: 7812 | G3: 1288980 | H3: 210.82 | I3: 2770 | J3: 583971.4 | K3: 1131 | L3: 238437.42 | M3: 1269 | N3: 267530.58 | O3: 河南
A4: 4 | B4: 101010115 | C4: 52°百年泸州老窖酒窖龄60年500ml | D4: 500ml*6 | E4: 200 | F4: 15612 | G4: 3122400 | H4: 264.02 | I4: 5498 | J4: 1451582 | K4: 2544 | L4: 671666.88 | M4: 2334 | N4: 616222.68 | O4: 河南
A5: 7 | B5: 101010036 | C5: 52°泸州老窖特曲500ml | D5: 500ml*6 | E5: 168 | F5: 85020 | G5: 14283360 | H5: 203.03 | I5: 46072 | J5: 9353998.2 | K5: 21635 | L5: 4392554 | M5: 21280 | N5: 4320478.4 | O5: 河南
A6: 8 | B6: 101010024 | C6: 52°泸州老窖头曲500ml | D6: 500ml*6 | E6: 37.87 | F6: 39000 | G6: 1476930 | H6: 60.09 | I6: 21460 | J6: 1289531.4 | K6: 7817 | L6: 469723.53 | M6: 9236 | N6: 554991.24 | O6: 河南
A7: 9 | B7: 101010503 | C7: 52°泸州老窖精品头曲D9 500ml | D7: 500ml*6 | E7: 75 | F7: 7962 | G7: 597150 | H7: 144.86 | I7: 2772 | J7: 401551.92 | K7: 1804 | L7: 261327.44 | M7: 1505 | N7: 218014.3 | O7: 河南
A8: 10 | B8: 101010502 | C8: 52°泸州老窖精品头曲D6 500ml | D8: 500ml*6 | E8: 63 | F8: 15606 | G8: 983178 | H8: 94.45 | I8: 2731 | J8: 257942.95 | K8: 718 | L8: 67815.1 | M8: 1235 | N8: 116645.75 | O8: 河南
A9: 11 | B9: 101010501 | C9: *42°泸小二FOR ME（彩色）酒125ml | D9: 125ml*24 | E9: 11 | F9: 0 | G9: 0 | H9: 11.93 | I9: 6343 | J9: 75671.99 | K9: 3600 | L9: 42948 | M9: 1564 | N9: 18658.52 | O9: 河南
A10: 12 | B10: 101010504 | C10: 42°泸州老窖二曲白酒蓝瓶装 500ml | D10: 500ml*6 | E10: 12 | F10: 0 | G10: 0 | H10: 19.93 | I10: 1986 | J10: 39580.98 | K10: 743 | L10: 14807.99 | M10: 767 | N10: 15286.31 | O10: 河南
A11: 13 | B11: 101010521 | C11: 52°国窖1573曾娜大师鉴藏版500ml | D11: 500ml*6 | E11: 740 | F11: 0 | G11: 0 | H11: 928.61 | I11: 201 | J11: 186650.61 | M11: 82 | N11: 76146.02 | O11: 河南
A12: 14 | B12: 101010525 | C12: 52°泸州老窖2018农历戊戌年金狗佑财1.088L | D12: 1.088L*3 | E12: 468 | F12: 0 | G12: 0 | H12: 408.05 | I12: 112 | J12: 45701.6 | M12: 25 | N12: 10201.25 | O12: 河南
A13: 15 | B13: 101020055 | C13: 52°泸州老窖中秋丁酉年节庆酒1L | D13: 1L*3 | E13: 268 | F13: 0 | G13: 0 | H13: 88.85 | I13: 261 | J13: 23189.85 | K13: 769 | L13: 68325.65 | M13: 46 | N13: 4087.1 | O13: 河南
A14: 16 | B14: 101020063 | C14: 53°国窖国韵1L | D14: 1L*1 | E14: 2220 | F14: 0 | G14: 0 | H14: 2536.98 | I14: 53 | J14: 134459.94 | M14: 49 | N14: 124312.02 | O14: 河南
A15: 竞品信息 | B15: 101010002 | C15: 52°剑南春普装500ml | D15: 500ml*6 | H15: =VLOOKUP(B15,河南!G:I,3,0) -> 379.66 | I15: 145885 | J15: =H15*I15 -> 55386699 | K15: 64698 | L15: 24563243 | M15: 66934 | N15: 25412162 | O15: 河南
A16: 竞品信息 | B16: 101010001 | C16: 52°五粮液普装500ml | D16: 500ml*6 | H16: =VLOOKUP(B16,河南!G:I,3,0) -> 879.83 | I16: 62803 | J16: =H16*I16 -> 55255963 | K16: 29753 | L16: 26177582 | M16: 27101 | N16: 23844273 | O16: 河南
A17: 竞品信息 | B17: 101010004 | C17: 52°洋河天之蓝480ml | D17: 480ml*6 | H17: =VLOOKUP(B17,河南!G:I,3,0) -> 346.05 | I17: 15225 | J17: =H17*I17 -> 5268611.2 | K17: 6887 | L17: 2383246.4 | M17: 7096 | N17: 2455570.8 | O17: 河南
A18: 竞品信息 | B18: 101010098 | C18: 52°洋河海之蓝480ml | D18: 480ml*6 | H18: =VLOOKUP(B18,河南!G:I,3,0) -> 145.4 | I18: 106074 | J18: =H18*I18 -> 15423160 | K18: 50409 | L18: =H18*K18 -> 7329468.6 | M18: 47800 | N18: =H18*M18 -> 6950120 | O18: 河南
A19: 1 | B19: 104020590 | C19: 舒富红葡萄酒750ml | D19: 750ml*6 | E19: 40.91 | F19: 53298 | G19: 2398410 | H19: 90.42 | I19: 56585 | J19: =E19*I19 -> 2314892.3 | K19: 3133 | L19: 283285.86 | M19: 19866 | N19: 1796283.7 | O19: 河南
A20: 2 | B20: 104020591 | C20: 希拉谷西拉红葡萄酒750ml | D20: 750ml*6 | E20: 90 | F20: 10008 | G20: 900720 | H20: 161.46 | I20: 14256 | J20: =E20*I20 -> 1283040 | K20: 1601 | L20: 258497.46 | M20: 10846 | N20: 1751195.2 | O20: 河南
A21: 3 | B21: 104020592 | C21: 希拉谷庄园西拉红葡萄酒750ml | D21: 750ml*6 | E21: 149 | F21: 7800 | G21: 1162200 | H21: 381.29 | I21: 794 | J21: =E21*I21 -> 118306 | K21: 790 | L21: 301219.1 | M21: 523 | N21: 199414.67 | O21: 河南
A22: 1 | B22: 101010397 | C22: 38°国窖1573 500ml | D22: 500ml*6 | E22: 530 | F22: 2880 | G22: 1526400 | H22: 654.03 | I22: 1628 | J22: 1064760.8 | K22: 1174 | L22: 767831.22 | M22: 1121 | N22: 733167.63 | O22: 北京
A23: 2 | B23: 101010099 | C23: 52°国窖1573 500ml | D23: 500ml*6 | E23: 740 | F23: 4890 | G23: 3618600 | H23: 824.19 | I23: 6445 | J23: 5311904.6 | K23: 1976 | L23: 1628599.4 | M23: 3602 | N23: 2968732.4 | O23: 北京
A24: 3 | B24: 101010114 | C24: *52°百年泸州老窖酒窖龄30年500ml | D24: 500ml*6 | E24: 165 | F24: 1140 | G24: 188100 | H24: 224.39 | I24: 1115 | J24: 250194.85 | K24: 241 | L24: 54077.99 | M24: 656 | N24: 147199.84 | O24: 北京
A25: 4 | B25: 101010115 | C25: 52°百年泸州老窖酒窖龄60年500ml | D25: 500ml*6 | E25: 200 | F25: 2640 | G25: 528000 | H25: 260.79 | I25: 2949 | J25: 769069.71 | K25: 782 | L25: 203937.78 | M25: 1387 | N25: 361715.73 | O25: 北京
A26: 5 | B26: 101010294 | C26: 38°泸州老窖泸州百年30年窖龄500ml | D26: 500ml*6 | E26: 145 | F26: 780 | G26: 113100 | H26: 200.19 | I26: 616 | J26: 123317.04 | K26: 353 | L26: 70667.07 | M26: 329 | N26: 65862.51 | O26: 北京
A27: 6 | B27: 101010297 | C27: 38°泸州老窖百年60年窖龄500ml | D27: 500ml*6 | E27: 180 | F27: 750 | G27: 135000 | H27: 240.7 | I27: 900 | J27: 216630 | K27: 359 | L27: 86411.3 | M27: 442 | N27: 106389.4 | O27: 北京
A28: 7 | B28: 101010036 | C28: 52°泸州老窖特曲500ml | D28: 500ml*6 | E28: 168 | F28: 3180 | G28: 534240 | H28: 210.81 | I28: 2451 | J28: 516695.31 | K28: 824 | L28: 173707.44 | M28: 1270 | N28: 267728.7 | O28: 北京
A29: 8 | B29: 101010024 | C29: 52°泸州老窖头曲500ml | D29: 500ml*6 | E29: 37.87 | F29: 1860 | G29: 70438.2 | H29: 61.43 | I29: 2092 | J29: 128511.56 | K29: 685 | L29: 42079.55 | M29: 1034 | N29: 63518.62 | O29: 北京
A30: 11 | B30: 101010501 | C30: *42°泸小二FOR ME（彩色）酒125ml | D30: 125ml*24 | E30: 11 | F30: 0 | G30: 0 | H30: 23.48 | I30: 1009 | J30: 23691.32 | K30: 526 | L30: 12350.48 | M30: 446 | N30: 10472.08 | O30: 北京
A31: 13 | B31: 101010521 | C31: 52°国窖1573曾娜大师鉴藏版500ml | D31: 500ml*6 | E31: 740 | F31: 0 | G31: 0 | H31: 952.33 | I31: 47 | J31: 44759.51 | M31: 47 | N31: 44759.51 | O31: 北京
A32: 15 | B32: 101020055 | C32: 52°泸州老窖中秋丁酉年节庆酒1L | D32: 1L*3 | E32: 268 | F32: 0 | G32: 0 | H32: 376.39 | I32: 32 | J32: 12044.48 | K32: 241 | L32: 90709.99 | M32: 14 | N32: 5269.46 | O32: 北京
A33: 16 | B33: 101020063 | C33: 53°国窖国韵1L | D33: 1L*1 | E33: 2220 | F33: 0 | G33: 0 | H33: 2918.67 | I33: 3 | J33: 8756.01 | M33: 3 | N33: 8756.01 | O33: 北京
A34: 竞品信息 | B34: 101010001 | C34: 52°五粮液普装500ml | D34: 500ml*6 | H34: 920.84 | I34: 10594 | J34: 9755379 | K34: 3578 | L34: 3294765.5 | M34: 5622 | N34: 5176962.5 | O34: 北京
A35: 竞品信息 | B35: 101010002 | C35: 52°剑南春普装500ml | D35: 500ml*6 | H35: 405.69 | I35: 8195 | J35: 3324629.5 | K35: 3662 | L35: 1485636.8 | M35: 4481 | N35: 1817896.9 | O35: 北京
A36: 竞品信息 | B36: 101010004 | C36: 52°洋河天之蓝480ml | D36: 480ml*6 | H36: 359 | I36: 286 | J36: 102674 | M36: 286 | N36: 102674 | O36: 北京
A37: 1 | B37: 104020590 | C37: 舒富红葡萄酒750ml | D37: 750ml*6 | E37: 40.91 | F37: 2400 | G37: 108000 | H37: 98.98 | I37: 7708 | J37: 762937.84 | K37: 200 | L37: 19796 | M37: 4509 | N37: 446300.82 | O37: 北京
A38: 2 | B38: 104020591 | C38: 希拉谷西拉红葡萄酒750ml | D38: 750ml*6 | E38: 90 | F38: 780 | G38: 70200 | H38: 230 | I38: 357 | J38: 82110 | K38: 15 | L38: 3450 | M38: 215 | N38: 49450 | O38: 北京
A39: 3 | B39: 104020592 | C39: 希拉谷庄园西拉红葡萄酒750ml | D39: 750ml*6 | E39: 149 | F39: 480 | G39: 71520 | H39: 396.43 | I39: 114 | J39: 45193.02 | K39: 10 | L39: 3964.3 | M39: 75 | N39: 29732.25 | O39: 北京
A40: 2 | B40: 101010099 | C40: 52°国窖1573 500ml | D40: 500ml*6 | E40: 740 | F40: 2760 | G40: 2042400 | H40: 822.69 | I40: 3297 | J40: =H40*I40 -> 2712408.9 | K40: 713 | L40: 586577.97 | M40: 1781 | N40: 1465210.9 | O40: 西安
...

Sheet 透视表
C3: 数据
A4: 商品名称 | B4: 地区 | C4: 求和项:2017.11-2018.10出库金额 | D4: 求和项:2017.5-2017.10出库金额 | E4: 求和项:2018.5-2018.10出库金额
A5: *42°泸小二FOR ME（彩色）酒125ml | B5: 北京 | C5: 23691.32 | D5: 12350.48 | E5: 10472.08
A6: *42°泸小二FOR ME（彩色）酒125ml | B6: 河南 | C6: 75671.99 | D6: 42948 | E6: 18658.52
A7: *42°泸小二FOR ME（彩色）酒125ml | B7: 西安 | C7: 24246.5 | D7: 5431.5 | E7: 11715
A8: *46°洋河海之蓝480ml | B8: 西安 | C8: 170198.83 | D8: 20225.73 | E8: 89571.09
A9: *52°百年泸州老窖酒窖龄30年500ml | B9: 北京 | C9: 250194.85 | D9: 54077.99 | E9: 147199.84
A10: *52°百年泸州老窖酒窖龄30年500ml | B10: 河南 | C10: 583971.4 | D10: 238437.42 | E10: 267530.58
A11: *52°百年泸州老窖酒窖龄30年500ml | B11: 西安 | C11: 135912.7 | D11: 59678.96 | E11: 63970.94
A12: *52°百年泸州老窖酒窖龄30年500ml | B12: 徐州 | C12: 2616 | E12: 1526
A13: 38°国窖1573 500ml | B13: 北京 | C13: 1064760.8 | D13: 767831.22 | E13: 733167.63
A14: 38°泸州老窖百年60年窖龄500ml | B14: 北京 | C14: 216630 | D14: 86411.3 | E14: 106389.4
A15: 38°泸州老窖泸州百年30年窖龄500ml | B15: 北京 | C15: 123317.04 | D15: 70667.07 | E15: 65862.51
A16: 42°泸州老窖二曲白酒蓝瓶装 500ml | B16: 河南 | C16: 39580.98 | D16: 14807.99 | E16: 15286.31
A17: 42°泸州老窖二曲白酒蓝瓶装 500ml | B17: 徐州 | C17: 550 | D17: 25 | E17: 425
A18: 42°洋河蓝色经典海之蓝480ml | B18: 徐州 | C18: 446936 | D18: 242.9 | E18: 294394.8
A19: 52°百年泸州老窖酒窖龄60年500ml | B19: 北京 | C19: 769069.71 | D19: 203937.78 | E19: 361715.73
A20: 52°百年泸州老窖酒窖龄60年500ml | B20: 河南 | C20: 1451582 | D20: 671666.88 | E20: 616222.68
A21: 52°百年泸州老窖酒窖龄60年500ml | B21: 西安 | C21: 244464.3 | D21: 43205.1 | E21: 110473.8
A22: 52°百年泸州老窖酒窖龄60年500ml | B22: 徐州 | C22: 7504 | E22: 3216
A23: 52°国窖1573 500ml | B23: 北京 | C23: 5311904.6 | D23: 1628599.4 | E23: 2968732.4
A24: 52°国窖1573 500ml | B24: 河南 | C24: 10892047 | D24: 4390187.3 | E24: 4146149.7
A25: 52°国窖1573 500ml | B25: 西安 | C25: 2712408.9 | D25: 586577.97 | E25: 1465210.9
A26: 52°国窖1573 500ml | B26: 徐州 | C26: 94002.44 | E26: 62391
A27: 52°国窖1573曾娜大师鉴藏版500ml | B27: 北京 | C27: 44759.51 | E27: 44759.51
A28: 52°国窖1573曾娜大师鉴藏版500ml | B28: 河南 | C28: 186650.61 | E28: 76146.02
A29: 52°国窖1573曾娜大师鉴藏版500ml | B29: 西安 | C29: 27076 | D29: 0 | E29: 27076
A30: 52°剑南春普装500ml | B30: 北京 | C30: 3324629.5 | D30: 1485636.8 | E30: 1817896.9
A31: 52°剑南春普装500ml | B31: 河南 | C31: 55386699 | D31: 24563243 | E31: 25412162
A32: 52°剑南春普装500ml | B32: 西安 | C32: 1414867.5 | D32: 416542.5 | E32: 644512.5
A33: 52°剑南春普装500ml | B33: 徐州 | C33: 64774.29 | E33: 38787
A34: 52°泸州老窖2018农历戊戌年金狗佑财1.088L | B34: 河南 | C34: 45701.6 | E34: 10201.25
A35: 52°泸州老窖精品头曲D6 500ml | B35: 河南 | C35: 257942.95 | D35: 67815.1 | E35: 116645.75
A36: 52°泸州老窖精品头曲D9 500ml | B36: 河南 | C36: 401551.92 | D36: 261327.44 | E36: 218014.3
A37: 52°泸州老窖特曲500ml | B37: 北京 | C37: 516695.31 | D37: 173707.44 | E37: 267728.7
A38: 52°泸州老窖特曲500ml | B38: 河南 | C38: 9353998.2 | D38: 4392554 | E38: 4320478.4
A39: 52°泸州老窖特曲500ml | B39: 西安 | C39: 316626.87 | D39: 73699.36 | E39: 193260.55
A40: 52°泸州老窖特曲500ml | B40: 徐州 | C40: 26453.7 | E40: 17215.9
A41: 52°泸州老窖头曲500ml | B41: 北京 | C41: 128511.56 | D41: 42079.55 | E41: 63518.62
A42: 52°泸州老窖头曲500ml | B42: 河南 | C42: 1289531.4 | D42: 469723.53 | E42: 554991.24
...

Sheet 过渡表
C3: 数据
A4: 商品名称 | B4: 地区 | C4: 求和项:2017.11-2018.10出库金额 | D4: 求和项:2017.5-2017.10出库金额 | E4: 求和项:2018.5-2018.10出库金额
A5: *42°泸小二FOR ME（彩色）酒125ml | B5: 北京 | C5: 23691.32 | D5: 12350.48 | E5: 10472.08
A6: *42°泸小二FOR ME（彩色）酒125ml | B6: 河南 | C6: 75671.99 | D6: 42948 | E6: 18658.52
A7: *42°泸小二FOR ME（彩色）酒125ml | B7: 西安 | C7: 24246.5 | D7: 5431.5 | E7: 11715
A8: *46°洋河海之蓝480ml | B8: 西安 | C8: 170198.83 | D8: 20225.73 | E8: 89571.09
A9: *52°百年泸州老窖酒窖龄30年500ml | B9: 北京 | C9: 250194.85 | D9: 54077.99 | E9: 147199.84
A10: *52°百年泸州老窖酒窖龄30年500ml | B10: 河南 | C10: 583971.4 | D10: 238437.42 | E10: 267530.58
A11: *52°百年泸州老窖酒窖龄30年500ml | B11: 西安 | C11: 135912.7 | D11: 59678.96 | E11: 63970.94
A12: *52°百年泸州老窖酒窖龄30年500ml | B12: 徐州 | C12: 2616 | E12: 1526
A13: 38°国窖1573 500ml | B13: 北京 | C13: 1064760.8 | D13: 767831.22 | E13: 733167.63
A14: 38°泸州老窖百年60年窖龄500ml | B14: 北京 | C14: 216630 | D14: 86411.3 | E14: 106389.4
A15: 38°泸州老窖泸州百年30年窖龄500ml | B15: 北京 | C15: 123317.04 | D15: 70667.07 | E15: 65862.51
A16: 42°泸州老窖二曲白酒蓝瓶装 500ml | B16: 河南 | C16: 39580.98 | D16: 14807.99 | E16: 15286.31
A17: 42°泸州老窖二曲白酒蓝瓶装 500ml | B17: 徐州 | C17: 550 | D17: 25 | E17: 425
A18: 42°洋河蓝色经典海之蓝480ml | B18: 徐州 | C18: 446936 | D18: 242.9 | E18: 294394.8
A19: 52°百年泸州老窖酒窖龄60年500ml | B19: 北京 | C19: 769069.71 | D19: 203937.78 | E19: 361715.73
A20: 52°百年泸州老窖酒窖龄60年500ml | B20: 河南 | C20: 1451582 | D20: 671666.88 | E20: 616222.68
A21: 52°百年泸州老窖酒窖龄60年500ml | B21: 西安 | C21: 244464.3 | D21: 43205.1 | E21: 110473.8
A22: 52°百年泸州老窖酒窖龄60年500ml | B22: 徐州 | C22: 7504 | E22: 3216
A23: 52°国窖1573 500ml | B23: 北京 | C23: 5311904.6 | D23: 1628599.4 | E23: 2968732.4
A24: 52°国窖1573 500ml | B24: 河南 | C24: 10892047 | D24: 4390187.3 | E24: 4146149.7
A25: 52°国窖1573 500ml | B25: 西安 | C25: 2712408.9 | D25: 586577.97 | E25: 1465210.9
A26: 52°国窖1573 500ml | B26: 徐州 | C26: 94002.44 | E26: 62391
A27: 52°国窖1573曾娜大师鉴藏版500ml | B27: 北京 | C27: 44759.51 | E27: 44759.51
A28: 52°国窖1573曾娜大师鉴藏版500ml | B28: 河南 | C28: 186650.61 | E28: 76146.02
A29: 52°国窖1573曾娜大师鉴藏版500ml | B29: 西安 | C29: 27076 | D29: 0 | E29: 27076
A30: 52°剑南春普装500ml | B30: 北京 | C30: 3324629.5 | D30: 1485636.8 | E30: 1817896.9
A31: 52°剑南春普装500ml | B31: 河南 | C31: 55386699 | D31: 24563243 | E31: 25412162
A32: 52°剑南春普装500ml | B32: 西安 | C32: 1414867.5 | D32: 416542.5 | E32: 644512.5
A33: 52°剑南春普装500ml | B33: 徐州 | C33: 64774.29 | E33: 38787
A34: 52°泸州老窖2018农历戊戌年金狗佑财1.088L | B34: 河南 | C34: 45701.6 | E34: 10201.25
A35: 52°泸州老窖精品头曲D6 500ml | B35: 河南 | C35: 257942.95 | D35: 67815.1 | E35: 116645.75
A36: 52°泸州老窖精品头曲D9 500ml | B36: 河南 | C36: 401551.92 | D36: 261327.44 | E36: 218014.3
A37: 52°泸州老窖特曲500ml | B37: 北京 | C37: 516695.31 | D37: 173707.44 | E37: 267728.7
A38: 52°泸州老窖特曲500ml | B38: 河南 | C38: 9353998.2 | D38: 4392554 | E38: 4320478.4
A39: 52°泸州老窖特曲500ml | B39: 西安 | C39: 316626.87 | D39: 73699.36 | E39: 193260.55
A40: 52°泸州老窖特曲500ml | B40: 徐州 | C40: 26453.7 | E40: 17215.9
A41: 52°泸州老窖头曲500ml | B41: 北京 | C41: 128511.56 | D41: 42079.55 | E41: 63518.62
A42: 52°泸州老窖头曲500ml | B42: 河南 | C42: 1289531.4 | D42: 469723.53 | E42: 554991.24
...

Sheet 整理后数据
C2: 地区 | D2: 2017年11月 至2018年10月 | E2: 2017年5月 至2017年10月 | F2: 2018年5月 至2018年10月
B3: 国窖1573 | C3: 北京 | D3: =SUMPRODUCT((透视表!$B$5:$B$67=整理后数据!$C3)*(透视表!C$5:C$67)*ISNUMBER(FIND(整理后数据!$B3,透视表!$A$5:$A$67))) -> 6421424.9 | E3: =SUMPRODUCT((透视表!$B$5:$B$67=整理后数据!$C3)*(透视表!D$5:D$67)*ISNUMBER(FIND(整理后数据!$B3,透视表!$A$5:$A$67))) -> 2396430.7 | F3: =SUMPRODUCT((透视表!$B$5:$B$67=整理后数据!$C3)*(透视表!E$5:E$67)*ISNUMBER(FIND(整理后数据!$B3,透视表!$A$5:$A$67))) -> 3746659.5
B4: 国窖1573 | C4: 河南 | D4: =SUMPRODUCT((透视表!$B$5:$B$67=整理后数据!$C4)*(透视表!C$5:C$67)*ISNUMBER(FIND(整理后数据!$B4,透视表!$A$5:$A$67))) -> 11078698 | E4: =SUMPRODUCT((透视表!$B$5:$B$67=整理后数据!$C4)*(透视表!D$5:D$67)*ISNUMBER(FIND(整理后数据!$B4,透视表!$A$5:$A$67))) -> 4390187.3 | F4: =SUMPRODUCT((透视表!$B$5:$B$67=整理后数据!$C4)*(透视表!E$5:E$67)*ISNUMBER(FIND(整理后数据!$B4,透视表!$A$5:$A$67))) -> 4222295.7
B5: 国窖1573 | C5: 西安 | D5: =SUMPRODUCT((透视表!$B$5:$B$67=整理后数据!$C5)*(透视表!C$5:C$67)*ISNUMBER(FIND(整理后数据!$B5,透视表!$A$5:$A$67))) -> 2739484.9 | E5: =SUMPRODUCT((透视表!$B$5:$B$67=整理后数据!$C5)*(透视表!D$5:D$67)*ISNUMBER(FIND(整理后数据!$B5,透视表!$A$5:$A$67))) -> 586577.97 | F5: =SUMPRODUCT((透视表!$B$5:$B$67=整理后数据!$C5)*(透视表!E$5:E$67)*ISNUMBER(FIND(整理后数据!$B5,透视表!$A$5:$A$67))) -> 1492286.9
B6: 国窖1573 | C6: 徐州 | D6: =SUMPRODUCT((透视表!$B$5:$B$67=整理后数据!$C6)*(透视表!C$5:C$67)*ISNUMBER(FIND(整理后数据!$B6,透视表!$A$5:$A$67))) -> 94002.44 | E6: =SUMPRODUCT((透视表!$B$5:$B$67=整理后数据!$C6)*(透视表!D$5:D$67)*ISNUMBER(FIND(整理后数据!$B6,透视表!$A$5:$A$67))) -> 0 | F6: =SUMPRODUCT((透视表!$B$5:$B$67=整理后数据!$C6)*(透视表!E$5:E$67)*ISNUMBER(FIND(整理后数据!$B6,透视表!$A$5:$A$67))) -> 62391
B7: 窖龄 | C7: 北京 | D7: =SUMPRODUCT((透视表!$B$5:$B$67=整理后数据!$C7)*(透视表!C$5:C$67)*ISNUMBER(FIND(整理后数据!$B7,透视表!$A$5:$A$67))) -> 1359211.6 | E7: =SUMPRODUCT((透视表!$B$5:$B$67=整理后数据!$C7)*(透视表!D$5:D$67)*ISNUMBER(FIND(整理后数据!$B7,透视表!$A$5:$A$67))) -> 415094.14 | F7: =SUMPRODUCT((透视表!$B$5:$B$67=整理后数据!$C7)*(透视表!E$5:E$67)*ISNUMBER(FIND(整理后数据!$B7,透视表!$A$5:$A$67))) -> 681167.48
B8: 窖龄 | C8: 河南 | D8: =SUMPRODUCT((透视表!$B$5:$B$67=整理后数据!$C8)*(透视表!C$5:C$67)*ISNUMBER(FIND(整理后数据!$B8,透视表!$A$5:$A$67))) -> 2035553.4 | E8: =SUMPRODUCT((透视表!$B$5:$B$67=整理后数据!$C8)*(透视表!D$5:D$67)*ISNUMBER(FIND(整理后数据!$B8,透视表!$A$5:$A$67))) -> 910104.3 | F8: =SUMPRODUCT((透视表!$B$5:$B$67=整理后数据!$C8)*(透视表!E$5:E$67)*ISNUMBER(FIND(整理后数据!$B8,透视表!$A$5:$A$67))) -> 883753.26
B9: 窖龄 | C9: 西安 | D9: =SUMPRODUCT((透视表!$B$5:$B$67=整理后数据!$C9)*(透视表!C$5:C$67)*ISNUMBER(FIND(整理后数据!$B9,透视表!$A$5:$A$67))) -> 380377 | E9: =SUMPRODUCT((透视表!$B$5:$B$67=整理后数据!$C9)*(透视表!D$5:D$67)*ISNUMBER(FIND(整理后数据!$B9,透视表!$A$5:$A$67))) -> 102884.06 | F9: =SUMPRODUCT((透视表!$B$5:$B$67=整理后数据!$C9)*(透视表!E$5:E$67)*ISNUMBER(FIND(整理后数据!$B9,透视表!$A$5:$A$67))) -> 174444.74
B10: 窖龄 | C10: 徐州 | D10: =SUMPRODUCT((透视表!$B$5:$B$67=整理后数据!$C10)*(透视表!C$5:C$67)*ISNUMBER(FIND(整理后数据!$B10,透视表!$A$5:$A$67))) -> 10120 | E10: =SUMPRODUCT((透视表!$B$5:$B$67=整理后数据!$C10)*(透视表!D$5:D$67)*ISNUMBER(FIND(整理后数据!$B10,透视表!$A$5:$A$67))) -> 0 | F10: =SUMPRODUCT((透视表!$B$5:$B$67=整理后数据!$C10)*(透视表!E$5:E$67)*ISNUMBER(FIND(整理后数据!$B10,透视表!$A$5:$A$67))) -> 4742
B11: 特曲 | C11: 北京 | D11: =SUMPRODUCT((透视表!$B$5:$B$67=整理后数据!$C11)*(透视表!C$5:C$67)*ISNUMBER(FIND(整理后数据!$B11,透视表!$A$5:$A$67))) -> 516695.31 | E11: =SUMPRODUCT((透视表!$B$5:$B$67=整理后数据!$C11)*(透视表!D$5:D$67)*ISNUMBER(FIND(整理后数据!$B11,透视表!$A$5:$A$67))) -> 173707.44 | F11: =SUMPRODUCT((透视表!$B$5:$B$67=整理后数据!$C11)*(透视表!E$5:E$67)*ISNUMBER(FIND(整理后数据!$B11,透视表!$A$5:$A$67))) -> 267728.7
B12: 特曲 | C12: 河南 | D12: =SUMPRODUCT((透视表!$B$5:$B$67=整理后数据!$C12)*(透视表!C$5:C$67)*ISNUMBER(FIND(整理后数据!$B12,透视表!$A$5:$A$67))) -> 9353998.2 | E12: =SUMPRODUCT((透视表!$B$5:$B$67=整理后数据!$C12)*(透视表!D$5:D$67)*ISNUMBER(FIND(整理后数据!$B12,透视表!$A$5:$A$67))) -> 4392554 | F12: =SUMPRODUCT((透视表!$B$5:$B$67=整理后数据!$C12)*(透视表!E$5:E$67)*ISNUMBER(FIND(整理后数据!$B12,透视表!$A$5:$A$67))) -> 4320478.4
B13: 特曲 | C13: 西安 | D13: =SUMPRODUCT((透视表!$B$5:$B$67=整理后数据!$C13)*(透视表!C$5:C$67)*ISNUMBER(FIND(整理后数据!$B13,透视表!$A$5:$A$67))) -> 316626.87 | E13: =SUMPRODUCT((透视表!$B$5:$B$67=整理后数据!$C13)*(透视表!D$5:D$67)*ISNUMBER(FIND(整理后数据!$B13,透视表!$A$5:$A$67))) -> 73699.36 | F13: =SUMPRODUCT((透视表!$B$5:$B$67=整理后数据!$C13)*(透视表!E$5:E$67)*ISNUMBER(FIND(整理后数据!$B13,透视表!$A$5:$A$67))) -> 193260.55
B14: 特曲 | C14: 徐州 | D14: =SUMPRODUCT((透视表!$B$5:$B$67=整理后数据!$C14)*(透视表!C$5:C$67)*ISNUMBER(FIND(整理后数据!$B14,透视表!$A$5:$A$67))) -> 26453.7 | E14: =SUMPRODUCT((透视表!$B$5:$B$67=整理后数据!$C14)*(透视表!D$5:D$67)*ISNUMBER(FIND(整理后数据!$B14,透视表!$A$5:$A$67))) -> 0 | F14: =SUMPRODUCT((透视表!$B$5:$B$67=整理后数据!$C14)*(透视表!E$5:E$67)*ISNUMBER(FIND(整理后数据!$B14,透视表!$A$5:$A$67))) -> 17215.9
... B34: 洋河 | C34: 徐州 | D34: =SUMPRODUCT((透视表!$B$5:$B$67=整理后数据!$C34)*(透视表!C$5:C$67)*ISNUMBER(FIND(整理后数据!$B34,透视表!$A$5:$A$67))) -> 446936 | E34: =SUMPRODUCT((透视表!$B$5:$B$67=整理后数据!$C34)*(透视表!D$5:D$67)*ISNUMBER(FIND(整理后数据!$B34,透视表!$A$5:$A$67))) -> 242.9 | F34: =SUMPRODUCT((透视表!$B$5:$B$67=整理后数据!$C34)*(透视表!E$5:E$67)*ISNUMBER(FIND(整理后数据!$B34,透视表!$A$5:$A$67))) -> 294394.8
B35: 其它 | C35: 北京 | D35: =D40-SUMIF($C$3:$C$34,$C35,D$3:D$34) -> 934732.67 | E35: =E40-SUMIF($C$3:$C$34,$C35,E$3:E$34) -> 130270.77 | F35: =F40-SUMIF($C$3:$C$34,$C35,F$3:F$34) -> 549980.62
B36: 其它 | C36: 河南 | D36: =D41-SUMIF($C$3:$C$34,$C36,D$3:D$34) -> 3995261.7 | E36: =E41-SUMIF($C$3:$C$34,$C36,E$3:E$34) -> 954276.07 | F36: =F41-SUMIF($C$3:$C$34,$C36,F$3:F$34) -> 3904152.4
B37: 其它 | C37: 西安 | D37: =D42-SUMIF($C$3:$C$34,$C37,D$3:D$34) -> 555543.05 | E37: =E42-SUMIF($C$3:$C$34,$C37,E$3:E$34) -> 45694.4 | F37: =F42-SUMIF($C$3:$C$34,$C37,F$3:F$34) -> 392240.72
B38: 其它 | C38: 徐州 | D38: =D43-SUMIF($C$3:$C$34,$C38,D$3:D$34) -> 40479.3 | E38: =E43-SUMIF($C$3:$C$34,$C38,E$3:E$34) -> 0 | F38: =F43-SUMIF($C$3:$C$34,$C38,F$3:F$34) -> 34654.23
B40: 辅助区域 | C40: 北京 | D40: 22543259 | E40: 7937984.9 | F40: 12406588
C41: 河南 | D41: 1.5978655e+08 | E41: 71914335 | F41: 72897743
C42: 西安 | D42: 10089848 | E42: 2105651.6 | F42: 5357434.5
C43: 徐州 | D43: 1120766.4 | E43: 7209.66 | F43: 747303.15

Sheet 图表
C2: 地区 | D2: 2017年11月 至2018年10月 | E2: 2017年5月 至2017年10月 | F2: 2018年5月 至2018年10月
B3: 国窖1573 | C3: 北京 | D3: 6421424.9 | E3: 2396430.7 | F3: 3746659.5
C4: 河南 | D4: 11078698 | E4: 4390187.3 | F4: 4222295.7
C5: 西安 | D5: 2739484.9 | E5: 586577.97 | F5: 1492286.9
C6: 徐州 | D6: 94002.44 | E6: 0 | F6: 62391
B7: 窖龄 | C7: 北京 | D7: 1359211.6 | E7: 415094.14 | F7: 681167.48
C8: 河南 | D8: 2035553.4 | E8: 910104.3 | F8: 883753.26
C9: 西安 | D9: 380377 | E9: 102884.06 | F9: 174444.74
C10: 徐州 | D10: 10120 | E10: 0 | F10: 4742
B11: 特曲 | C11: 北京 | D11: 516695.31 | E11: 173707.44 | F11: 267728.7
C12: 河南 | D12: 9353998.2 | E12: 4392554 | F12: 4320478.4
C13: 西安 | D13: 316626.87 | E13: 73699.36 | F13: 193260.55
