Workbook
Name 汇总表首行: 成绩汇总表!#REF!

Sheet 成绩汇总表
A3: 考试类别 | B3: 学号 | C3: 姓名 | D3: 数学 | E3: 排名 | F3: 语文 | G3: 排名 | H3: 外语 | I3: 排名 | J3: 生物 | K3: 排名 | L3: 总分 | M3: 总名次
A4: 1月月考 | B4: A01 | C4: =IF(B4="","",VLOOKUP(B4,学生信息汇总!A:E,2,0)) -> 名字1 | D4: 85 | E4: =RANK(D4,$D$4:$D$13) -> 5 | F4: 85 | G4: =RANK(F4,$F$4:$F$13) -> 6 | H4: 100 | I4: =RANK(H4,$H$4:$H$13) -> 1 | J4: 92 | K4: =RANK(J4,$J$4:$J$13) -> 2 | L4: =D4+F4+H4+J4 -> 362 | M4: =RANK(L4,$L$4:$L$13) -> 2
A5: 1月月考 | B5: A02 | C5: =IF(B5="","",VLOOKUP(B5,学生信息汇总!A:E,2,0)) -> 名字2 | D5: 93 | E5: =RANK(D5,$D$4:$D$13) -> 2 | F5: 93 | G5: =RANK(F5,$F$4:$F$13) -> 2 | H5: 80 | I5: =RANK(H5,$H$4:$H$13) -> 9 | J5: 80 | K5: =RANK(J5,$J$4:$J$13) -> 3 | L5: =D5+F5+H5+J5 -> 346 | M5: =RANK(L5,$L$4:$L$13) -> 4
A6: 1月月考 | B6: A03 | C6: =IF(B6="","",VLOOKUP(B6,学生信息汇总!A:E,2,0)) -> 名字3 | D6: 90 | E6: =RANK(D6,$D$4:$D$13) -> 3 | F6: 92 | G6: =RANK(F6,$F$4:$F$13) -> 3 | H6: 85 | I6: =RANK(H6,$H$4:$H$13) -> 7 | J6: 80 | K6: =RANK(J6,$J$4:$J$13) -> 3 | L6: =D6+F6+H6+J6 -> 347 | M6: =RANK(L6,$L$4:$L$13) -> 3
A7: 1月月考 | B7: A04 | C7: =IF(B7="","",VLOOKUP(B7,学生信息汇总!A:E,2,0)) -> 名字4 | D7: 75 | E7: =RANK(D7,$D$4:$D$13) -> 7 | F7: 75 | G7: =RANK(F7,$F$4:$F$13) -> 8 | H7: 85 | I7: =RANK(H7,$H$4:$H$13) -> 7 | J7: 75 | K7: =RANK(J7,$J$4:$J$13) -> 5 | L7: =D7+F7+H7+J7 -> 310 | M7: =RANK(L7,$L$4:$L$13) -> 6
A8: 1月月考 | B8: A05 | C8: =IF(B8="","",VLOOKUP(B8,学生信息汇总!A:E,2,0)) -> 名字5 | D8: 88 | E8: =RANK(D8,$D$4:$D$13) -> 4 | F8: 88 | G8: =RANK(F8,$F$4:$F$13) -> 5 | H8: 89 | I8: =RANK(H8,$H$4:$H$13) -> 5 | J8: 70 | K8: =RANK(J8,$J$4:$J$13) -> 6 | L8: =D8+F8+H8+J8 -> 335 | M8: =RANK(L8,$L$4:$L$13) -> 5
A9: 1月月考 | B9: A06 | C9: =IF(B9="","",VLOOKUP(B9,学生信息汇总!A:E,2,0)) -> 名字6 | D9: 55 | E9: =RANK(D9,$D$4:$D$13) -> 9 | F9: 90 | G9: =RANK(F9,$F$4:$F$13) -> 4 | H9: 95 | I9: =RANK(H9,$H$4:$H$13) -> 2 | J9: 65 | K9: =RANK(J9,$J$4:$J$13) -> 7 | L9: =D9+F9+H9+J9 -> 305 | M9: =RANK(L9,$L$4:$L$13) -> 7
A10: 1月月考 | B10: A07 | C10: =IF(B10="","",VLOOKUP(B10,学生信息汇总!A:E,2,0)) -> 名字7 | D10: 60 | E10: =RANK(D10,$D$4:$D$13) -> 8 | F10: 60 | G10: =RANK(F10,$F$4:$F$13) -> 9 | H10: 95 | I10: =RANK(H10,$H$4:$H$13) -> 2 | J10: 60 | K10: =RANK(J10,$J$4:$J$13) -> 8 | L10: =D10+F10+H10+J10 -> 275 | M10: =RANK(L10,$L$4:$L$13) -> 9
A11: 1月月考 | B11: A08 | C11: =IF(B11="","",VLOOKUP(B11,学生信息汇总!A:E,2,0)) -> 名字8 | D11: 55 | E11: =RANK(D11,$D$4:$D$13) -> 9 | F11: 55 | G11: =RANK(F11,$F$4:$F$13) -> 10 | H11: 80 | I11: =RANK(H11,$H$4:$H$13) -> 9 | J11: 55 | K11: =RANK(J11,$J$4:$J$13) -> 9 | L11: =D11+F11+H11+J11 -> 245 | M11: =RANK(L11,$L$4:$L$13) -> 10
A12: 1月月考 | B12: A09 | C12: =IF(B12="","",VLOOKUP(B12,学生信息汇总!A:E,2,0)) -> 名字9 | D12: 78 | E12: =RANK(D12,$D$4:$D$13) -> 6 | F12: 78 | G12: =RANK(F12,$F$4:$F$13) -> 7 | H12: 89 | I12: =RANK(H12,$H$4:$H$13) -> 5 | J12: 50 | K12: =RANK(J12,$J$4:$J$13) -> 10 | L12: =D12+F12+H12+J12 -> 295 | M12: =RANK(L12,$L$4:$L$13) -> 8
A13: 1月月考 | B13: A10 | C13: =IF(B13="","",VLOOKUP(B13,学生信息汇总!A:E,2,0)) -> 名字10 | D13: 95 | E13: =RANK(D13,$D$4:$D$13) -> 1 | F13: 95 | G13: =RANK(F13,$F$4:$F$13) -> 1 | H13: 95 | I13: =RANK(H13,$H$4:$H$13) -> 2 | J13: 95 | K13: =RANK(J13,$J$4:$J$13) -> 1 | L13: =D13+F13+H13+J13 -> 380 | M13: =RANK(L13,$L$4:$L$13) -> 1
A14: 期中考试 | B14: A01 | C14: =IF(B14="","",VLOOKUP(B14,学生信息汇总!A:E,2,0)) -> 名字1 | D14: 89 | E14: =RANK(D14,$D$14:$D$23) -> 4 | F14: 89 | G14: =RANK(F14,$F$14:$F$23) -> 4 | H14: 81 | I14: =RANK(H14,$H$14:$H$23) -> 9 | J14: 95 | K14: =RANK(J14,$J$14:$J$23) -> 2 | L14: =D14+F14+H14+J14 -> 354 | M14: =RANK(L14,$L$14:$L$23) -> 5
A15: 期中考试 | B15: A02 | C15: =IF(B15="","",VLOOKUP(B15,学生信息汇总!A:E,2,0)) -> 名字2 | D15: 80 | E15: =RANK(D15,$D$14:$D$23) -> 9 | F15: 80 | G15: =RANK(F15,$F$14:$F$23) -> 8 | H15: 55 | I15: =RANK(H15,$H$14:$H$23) -> 10 | J15: 100 | K15: =RANK(J15,$J$14:$J$23) -> 1 | L15: =D15+F15+H15+J15 -> 315 | M15: =RANK(L15,$L$14:$L$23) -> 9
A16: 期中考试 | B16: A03 | C16: =IF(B16="","",VLOOKUP(B16,学生信息汇总!A:E,2,0)) -> 名字3 | D16: 85 | E16: =RANK(D16,$D$14:$D$23) -> 7 | F16: 56 | G16: =RANK(F16,$F$14:$F$23) -> 10 | H16: 83 | I16: =RANK(H16,$H$14:$H$23) -> 8 | J16: 89 | K16: =RANK(J16,$J$14:$J$23) -> 5 | L16: =D16+F16+H16+J16 -> 313 | M16: =RANK(L16,$L$14:$L$23) -> 10
A17: 期中考试 | B17: A04 | C17: =IF(B17="","",VLOOKUP(B17,学生信息汇总!A:E,2,0)) -> 名字4 | D17: 85 | E17: =RANK(D17,$D$14:$D$23) -> 7 | F17: 85 | G17: =RANK(F17,$F$14:$F$23) -> 7 | H17: 84 | I17: =RANK(H17,$H$14:$H$23) -> 7 | J17: 80 | K17: =RANK(J17,$J$14:$J$23) -> 10 | L17: =D17+F17+H17+J17 -> 334 | M17: =RANK(L17,$L$14:$L$23) -> 8
A18: 期中考试 | B18: A05 | C18: =IF(B18="","",VLOOKUP(B18,学生信息汇总!A:E,2,0)) -> 名字5 | D18: 89 | E18: =RANK(D18,$D$14:$D$23) -> 4 | F18: 89 | G18: =RANK(F18,$F$14:$F$23) -> 4 | H18: 85 | I18: =RANK(H18,$H$14:$H$23) -> 6 | J18: 85 | K18: =RANK(J18,$J$14:$J$23) -> 8 | L18: =D18+F18+H18+J18 -> 348 | M18: =RANK(L18,$L$14:$L$23) -> 6
A19: 期中考试 | B19: A06 | C19: =IF(B19="","",VLOOKUP(B19,学生信息汇总!A:E,2,0)) -> 名字6 | D19: 95 | E19: =RANK(D19,$D$14:$D$23) -> 2 | F19: 95 | G19: =RANK(F19,$F$14:$F$23) -> 1 | H19: 86 | I19: =RANK(H19,$H$14:$H$23) -> 5 | J19: 81 | K19: =RANK(J19,$J$14:$J$23) -> 9 | L19: =D19+F19+H19+J19 -> 357 | M19: =RANK(L19,$L$14:$L$23) -> 4
A20: 期中考试 | B20: A07 | C20: =IF(B20="","",VLOOKUP(B20,学生信息汇总!A:E,2,0)) -> 名字7 | D20: 95 | E20: =RANK(D20,$D$14:$D$23) -> 2 | F20: 95 | G20: =RANK(F20,$F$14:$F$23) -> 1 | H20: 87 | I20: =RANK(H20,$H$14:$H$23) -> 4 | J20: 88 | K20: =RANK(J20,$J$14:$J$23) -> 6 | L20: =D20+F20+H20+J20 -> 365 | M20: =RANK(L20,$L$14:$L$23) -> 2
A21: 期中考试 | B21: A08 | C21: =IF(B21="","",VLOOKUP(B21,学生信息汇总!A:E,2,0)) -> 名字8 | D21: 80 | E21: =RANK(D21,$D$14:$D$23) -> 9 | F21: 80 | G21: =RANK(F21,$F$14:$F$23) -> 8 | H21: 88 | I21: =RANK(H21,$H$14:$H$23) -> 3 | J21: 90 | K21: =RANK(J21,$J$14:$J$23) -> 4 | L21: =D21+F21+H21+J21 -> 338 | M21: =RANK(L21,$L$14:$L$23) -> 7
A22: 期中考试 | B22: A09 | C22: =IF(B22="","",VLOOKUP(B22,学生信息汇总!A:E,2,0)) -> 名字9 | D22: 89 | E22: =RANK(D22,$D$14:$D$23) -> 4 | F22: 89 | G22: =RANK(F22,$F$14:$F$23) -> 4 | H22: 89 | I22: =RANK(H22,$H$14:$H$23) -> 2 | J22: 93 | K22: =RANK(J22,$J$14:$J$23) -> 3 | L22: =D22+F22+H22+J22 -> 360 | M22: =RANK(L22,$L$14:$L$23) -> 3
A23: 期中考试 | B23: A10 | C23: =IF(B23="","",VLOOKUP(B23,学生信息汇总!A:E,2,0)) -> 名字10 | D23: 96 | E23: =RANK(D23,$D$14:$D$23) -> 1 | F23: 95 | G23: =RANK(F23,$F$14:$F$23) -> 1 | H23: 90 | I23: =RANK(H23,$H$14:$H$23) -> 1 | J23: 87 | K23: =RANK(J23,$J$14:$J$23) -> 7 | L23: =D23+F23+H23+J23 -> 368 | M23: =RANK(L23,$L$14:$L$23) -> 1
A24: 5月月考 | B24: A01 | C24: =IF(B24="","",VLOOKUP(B24,学生信息汇总!A:E,2,0)) -> 名字1 | D24: 95 | E24: =RANK(D24,$D$24:$D$33) -> 1 | F24: 95 | G24: =RANK(F24,$F$24:$F$33) -> 1 | H24: 80 | I24: =RANK(H24,$H$24:$H$33) -> 3 | J24: 100 | K24: =RANK(J24,$J$24:$J$33) -> 1 | L24: =D24+F24+H24+J24 -> 370 | M24: =RANK(L24,$L$24:$L$33) -> 1
A25: 5月月考 | B25: A02 | C25: =IF(B25="","",VLOOKUP(B25,学生信息汇总!A:E,2,0)) -> 名字2 | D25: 81 | E25: =RANK(D25,$D$24:$D$33) -> 9 | F25: 81 | G25: =RANK(F25,$F$24:$F$33) -> 10 | H25: 75 | I25: =RANK(H25,$H$24:$H$33) -> 5 | J25: 80 | K25: =RANK(J25,$J$24:$J$33) -> 9 | L25: =D25+F25+H25+J25 -> 317 | M25: =RANK(L25,$L$24:$L$33) -> 6
A26: 5月月考 | B26: A03 | C26: =IF(B26="","",VLOOKUP(B26,学生信息汇总!A:E,2,0)) -> 名字3 | D26: 82 | E26: =RANK(D26,$D$24:$D$33) -> 8 | F26: 82 | G26: =RANK(F26,$F$24:$F$33) -> 9 | H26: 70 | I26: =RANK(H26,$H$24:$H$33) -> 6 | J26: 85 | K26: =RANK(J26,$J$24:$J$33) -> 7 | L26: =D26+F26+H26+J26 -> 319 | M26: =RANK(L26,$L$24:$L$33) -> 5
A27: 5月月考 | B27: A04 | C27: =IF(B27="","",VLOOKUP(B27,学生信息汇总!A:E,2,0)) -> 名字4 | D27: 83 | E27: =RANK(D27,$D$24:$D$33) -> 7 | F27: 83 | G27: =RANK(F27,$F$24:$F$33) -> 8 | H27: 65 | I27: =RANK(H27,$H$24:$H$33) -> 7 | J27: 85 | K27: =RANK(J27,$J$24:$J$33) -> 7 | L27: =D27+F27+H27+J27 -> 316 | M27: =RANK(L27,$L$24:$L$33) -> 9
A28: 5月月考 | B28: A05 | C28: =IF(B28="","",VLOOKUP(B28,学生信息汇总!A:E,2,0)) -> 名字5 | D28: 84 | E28: =RANK(D28,$D$24:$D$33) -> 6 | F28: 84 | G28: =RANK(F28,$F$24:$F$33) -> 7 | H28: 60 | I28: =RANK(H28,$H$24:$H$33) -> 8 | J28: 89 | K28: =RANK(J28,$J$24:$J$33) -> 5 | L28: =D28+F28+H28+J28 -> 317 | M28: =RANK(L28,$L$24:$L$33) -> 6
A29: 5月月考 | B29: A06 | C29: =IF(B29="","",VLOOKUP(B29,学生信息汇总!A:E,2,0)) -> 名字6 | D29: 55 | E29: =RANK(D29,$D$24:$D$33) -> 10 | F29: 85 | G29: =RANK(F29,$F$24:$F$33) -> 6 | H29: 55 | I29: =RANK(H29,$H$24:$H$33) -> 9 | J29: 95 | K29: =RANK(J29,$J$24:$J$33) -> 2 | L29: =D29+F29+H29+J29 -> 290 | M29: =RANK(L29,$L$24:$L$33) -> 10
A30: 5月月考 | B30: A07 | C30: =IF(B30="","",VLOOKUP(B30,学生信息汇总!A:E,2,0)) -> 名字7 | D30: 86 | E30: =RANK(D30,$D$24:$D$33) -> 5 | F30: 86 | G30: =RANK(F30,$F$24:$F$33) -> 5 | H30: 50 | I30: =RANK(H30,$H$24:$H$33) -> 10 | J30: 95 | K30: =RANK(J30,$J$24:$J$33) -> 2 | L30: =D30+F30+H30+J30 -> 317 | M30: =RANK(L30,$L$24:$L$33) -> 6
A31: 5月月考 | B31: A08 | C31: =IF(B31="","",VLOOKUP(B31,学生信息汇总!A:E,2,0)) -> 名字8 | D31: 87 | E31: =RANK(D31,$D$24:$D$33) -> 4 | F31: 87 | G31: =RANK(F31,$F$24:$F$33) -> 4 | H31: 95 | I31: =RANK(H31,$H$24:$H$33) -> 1 | J31: 80 | K31: =RANK(J31,$J$24:$J$33) -> 9 | L31: =D31+F31+H31+J31 -> 349 | M31: =RANK(L31,$L$24:$L$33) -> 3
A32: 5月月考 | B32: A09 | C32: =IF(B32="","",VLOOKUP(B32,学生信息汇总!A:E,2,0)) -> 名字9 | D32: 88 | E32: =RANK(D32,$D$24:$D$33) -> 3 | F32: 88 | G32: =RANK(F32,$F$24:$F$33) -> 3 | H32: 81 | I32: =RANK(H32,$H$24:$H$33) -> 2 | J32: 89 | K32: =RANK(J32,$J$24:$J$33) -> 5 | L32: =D32+F32+H32+J32 -> 346 | M32: =RANK(L32,$L$24:$L$33) -> 4
A33: 5月月考 | B33: A10 | C33: =IF(B33="","",VLOOKUP(B33,学生信息汇总!A:E,2,0)) -> 名字10 | D33: 89 | E33: =RANK(D33,$D$24:$D$33) -> 2 | F33: 89 | G33: =RANK(F33,$F$24:$F$33) -> 2 | H33: 80 | I33: =RANK(H33,$H$24:$H$33) -> 3 | J33: 95 | K33: =RANK(J33,$J$24:$J$33) -> 2 | L33: =D33+F33+H33+J33 -> 353 | M33: =RANK(L33,$L$24:$L$33) -> 2
A34: 期末考试 | B34: A01 | C34: =IF(B34="","",VLOOKUP(B34,学生信息汇总!A:E,2,0)) -> 名字1 | D34: 90 | E34: =RANK(D34,$D$34:$D$43) -> 3 | F34: 90 | G34: =RANK(F34,$F$34:$F$43) -> 3 | H34: 89 | I34: =RANK(H34,$H$34:$H$43) -> 3 | J34: 81 | K34: =RANK(J34,$J$34:$J$43) -> 8 | L34: =D34+F34+H34+J34 -> 350 | M34: =RANK(L34,$L$34:$L$43) -> 3
A35: 期末考试 | B35: A02 | C35: =IF(B35="","",VLOOKUP(B35,学生信息汇总!A:E,2,0)) -> 名字2 | D35: 81 | E35: =RANK(D35,$D$34:$D$43) -> 8 | F35: 65 | G35: =RANK(F35,$F$34:$F$43) -> 7 | H35: 80 | I35: =RANK(H35,$H$34:$H$43) -> 9 | J35: 82 | K35: =RANK(J35,$J$34:$J$43) -> 7 | L35: =D35+F35+H35+J35 -> 308 | M35: =RANK(L35,$L$34:$L$43) -> 8
A36: 期末考试 | B36: A03 | C36: =IF(B36="","",VLOOKUP(B36,学生信息汇总!A:E,2,0)) -> 名字3 | D36: 80 | E36: =RANK(D36,$D$34:$D$43) -> 9 | F36: 60 | G36: =RANK(F36,$F$34:$F$43) -> 8 | H36: 85 | I36: =RANK(H36,$H$34:$H$43) -> 5 | J36: 83 | K36: =RANK(J36,$J$34:$J$43) -> 6 | L36: =D36+F36+H36+J36 -> 308 | M36: =RANK(L36,$L$34:$L$43) -> 8
A37: 期末考试 | B37: A04 | C37: =IF(B37="","",VLOOKUP(B37,学生信息汇总!A:E,2,0)) -> 名字4 | D37: 89 | E37: =RANK(D37,$D$34:$D$43) -> 4 | F37: 55 | G37: =RANK(F37,$F$34:$F$43) -> 9 | H37: 85 | I37: =RANK(H37,$H$34:$H$43) -> 5 | J37: 84 | K37: =RANK(J37,$J$34:$J$43) -> 5 | L37: =D37+F37+H37+J37 -> 313 | M37: =RANK(L37,$L$34:$L$43) -> 7
A38: 期末考试 | B38: A05 | C38: =IF(B38="","",VLOOKUP(B38,学生信息汇总!A:E,2,0)) -> 名字5 | D38: 80 | E38: =RANK(D38,$D$34:$D$43) -> 9 | F38: 50 | G38: =RANK(F38,$F$34:$F$43) -> 10 | H38: 89 | I38: =RANK(H38,$H$34:$H$43) -> 3 | J38: 55 | K38: =RANK(J38,$J$34:$J$43) -> 10 | L38: =D38+F38+H38+J38 -> 274 | M38: =RANK(L38,$L$34:$L$43) -> 10
A39: 期末考试 | B39: A06 | C39: =IF(B39="","",VLOOKUP(B39,学生信息汇总!A:E,2,0)) -> 名字6 | D39: 85 | E39: =RANK(D39,$D$34:$D$43) -> 6 | F39: 95 | G39: =RANK(F39,$F$34:$F$43) -> 2 | H39: 95 | I39: =RANK(H39,$H$34:$H$43) -> 1 | J39: 86 | K39: =RANK(J39,$J$34:$J$43) -> 4 | L39: =D39+F39+H39+J39 -> 361 | M39: =RANK(L39,$L$34:$L$43) -> 1
A40: 期末考试 | B40: A07 | C40: =IF(B40="","",VLOOKUP(B40,学生信息汇总!A:E,2,0)) -> 名字7 | D40: 85 | E40: =RANK(D40,$D$34:$D$43) -> 6 | F40: 81 | G40: =RANK(F40,$F$34:$F$43) -> 5 | H40: 95 | I40: =RANK(H40,$H$34:$H$43) -> 1 | J40: 87 | K40: =RANK(J40,$J$34:$J$43) -> 3 | L40: =D40+F40+H40+J40 -> 348 | M40: =RANK(L40,$L$34:$L$43) -> 4
A41: 期末考试 | B41: A08 | C41: =IF(B41="","",VLOOKUP(B41,学生信息汇总!A:E,2,0)) -> 名字8 | D41: 89 | E41: =RANK(D41,$D$34:$D$43) -> 4 | F41: 80 | G41: =RANK(F41,$F$34:$F$43) -> 6 | H41: 80 | I41: =RANK(H41,$H$34:$H$43) -> 9 | J41: 88 | K41: =RANK(J41,$J$34:$J$43) -> 2 | L41: =D41+F41+H41+J41 -> 337 | M41: =RANK(L41,$L$34:$L$43) -> 6
A42: 期末考试 | B42: A09 | C42: =IF(B42="","",VLOOKUP(B42,学生信息汇总!A:E,2,0)) -> 名字9 | D42: 98 | E42: =RANK(D42,$D$34:$D$43) -> 1 | F42: 89 | G42: =RANK(F42,$F$34:$F$43) -> 4 | H42: 81 | I42: =RANK(H42,$H$34:$H$43) -> 8 | J42: 89 | K42: =RANK(J42,$J$34:$J$43) -> 1 | L42: =D42+F42+H42+J42 -> 357 | M42: =RANK(L42,$L$34:$L$43) -> 2
...

Sheet 图表分析
A2: 平均分
A3: 考试类别 | B3: 数学 | C3: 语文 | D3: 外语 | E3: 生物 | F3: 总分
A4: 1月月考 | B4: =SUM(成绩汇总表!D4:D13)/10 -> 77.4 | C4: =SUM(成绩汇总表!F4:F13)/10 -> 81.1 | D4: =SUM(成绩汇总表!H4:H13)/10 -> 89.3 | E4: =SUM(成绩汇总表!J4:J13)/10 -> 72.2 | F4: =SUM(成绩汇总表!L4:L13)/10 -> 320
A5: 期中考试 | B5: =SUM(成绩汇总表!D14:D23)/10 -> 88.3 | C5: =SUM(成绩汇总表!F14:F23)/10 -> 85.3 | D5: =SUM(成绩汇总表!H14:H23)/10 -> 82.8 | E5: =SUM(成绩汇总表!J14:J23)/10 -> 88.8 | F5: =SUM(成绩汇总表!L5:L14)/10 -> 319.2
A6: 5月月考 | B6: =SUM(成绩汇总表!D24:D33)/10 -> 83 | C6: =SUM(成绩汇总表!F24:F33)/10 -> 86 | D6: =SUM(成绩汇总表!H24:H33)/10 -> 71.1 | E6: =SUM(成绩汇总表!J24:J33)/10 -> 89.3 | F6: =SUM(成绩汇总表!L24:L33)/10 -> 329.4
A7: 期末考试 | B7: =SUM(成绩汇总表!D34:D43)/10 -> 87.2 | C7: =SUM(成绩汇总表!F34:F43)/10 -> 76.4 | D7: =SUM(成绩汇总表!H34:H43)/10 -> 86.4 | E7: =SUM(成绩汇总表!J34:J43)/10 -> 80.1 | F7: =SUM(成绩汇总表!L34:L43)/10 -> 330.1
H9: 个人成绩分析组合表
A11: 历史成绩分析，输入学号即可；柱形为所选科目成绩，低于60分，柱形即为红色；上方折线为成绩排名；
A12: 学号 | B12: A06 | C12: 姓名： | E12: =VLOOKUP(B12,学生信息汇总!A:B,2,0) -> 名字6 | O12: 个人单科成绩分析图
A13: 成绩 | H13: 1 | I13: 成绩 | J13: 排名 | K13: 表5 | L13: 排名 | Q13: 1
B14: 数学 | C14: 语文 | D14: 外语 | E14: 生物 | F14: 总分 | H14: 数学 | I14: =INDEX(B14:G14,$H$13) -> 数学 | J14: =INDEX(L14:V14,$H$13) -> 数学 | K14: 60分及格 | L14: 数学 | M14: 语文 | N14: 外语 | O14: 生物 | P14: 总分 | R14: 成绩 | S14: 排名 | T14: 辅助
A15: 1月月考 | B15: {=VLOOKUP($A15&$B$12,IF({1,0},成绩汇总表!$A$1:$A$9961&成绩汇总表!$B$1:$B$9961,成绩汇总表!$D$1:$D$9961),2,0)} -> 55 | C15: {=VLOOKUP($A15&$B$12,IF({1,0},成绩汇总表!$A$1:$A$9961&成绩汇总表!$B$1:$B$9961,成绩汇总表!$F$1:$F$9961),2,0)} -> 90 | D15: {=VLOOKUP($A15&$B$12,IF({1,0},成绩汇总表!$A$1:$A$9961&成绩汇总表!$B$1:$B$9961,成绩汇总表!$H$1:$H$9961),2,0)} -> 95 | E15: {=VLOOKUP($A15&$B$12,IF({1,0},成绩汇总表!$A$1:$A$9961&成绩汇总表!$B$1:$B$9961,成绩汇总表!$J$1:$J$9961),2,0)} -> 65 | F15: {=VLOOKUP($A15&$B$12,IF({1,0},成绩汇总表!$A$1:$A$9961&成绩汇总表!$B$1:$B$9961,成绩汇总表!$L$1:$L$9961),2,0)} -> 305 | H15: 语文 | I15: =INDEX(B15:F15,$H$13) -> 55 | J15: =INDEX(L15:V15,$H$13) -> 9 | K15: =IF(I15<60,I15,#N/A) -> 55 | L15: {=VLOOKUP($A15&$B$12,IF({1,0},成绩汇总表!$A$1:$A$9961&成绩汇总表!$B$1:$B$9961,成绩汇总表!$E$1:$E$9961),2,0)} -> 9 | M15: {=VLOOKUP($A15&$B$12,IF({1,0},成绩汇总表!$A$1:$A$9961&成绩汇总表!$B$1:$B$9961,成绩汇总表!$G$1:$G$9961),2,0)} -> 4 | N15: {=VLOOKUP($A15&$B$12,IF({1,0},成绩汇总表!$A$1:$A$9961&成绩汇总表!$B$1:$B$9961,成绩汇总表!$I$1:$I$9961),2,0)} -> 2 | O15: {=VLOOKUP($A15&$B$12,IF({1,0},成绩汇总表!$A$1:$A$9961&成绩汇总表!$B$1:$B$9961,成绩汇总表!$K$1:$K$9961),2,0)} -> 7 | P15: {=VLOOKUP($A15&$B$12,IF({1,0},成绩汇总表!$A$1:$A$9961&成绩汇总表!$B$1:$B$9961,成绩汇总表!$M$1:$M$9961),2,0)} -> 7 | R15: =INDEX(B15:F15,$Q$13) -> 55 | S15: =INDEX(L15:P15,$Q$13) -> 9 | T15: =IF(R15<60,R15,NA()) -> 55
A16: 期中考试 | B16: {=VLOOKUP($A16&$B$12,IF({1,0},成绩汇总表!$A$1:$A$9961&成绩汇总表!$B$1:$B$9961,成绩汇总表!$D$1:$D$9961),2,0)} -> 95 | C16: {=VLOOKUP($A16&$B$12,IF({1,0},成绩汇总表!$A$1:$A$9961&成绩汇总表!$B$1:$B$9961,成绩汇总表!$F$1:$F$9961),2,0)} -> 95 | D16: {=VLOOKUP($A16&$B$12,IF({1,0},成绩汇总表!$A$1:$A$9961&成绩汇总表!$B$1:$B$9961,成绩汇总表!$H$1:$H$9961),2,0)} -> 86 | E16: {=VLOOKUP($A16&$B$12,IF({1,0},成绩汇总表!$A$1:$A$9961&成绩汇总表!$B$1:$B$9961,成绩汇总表!$J$1:$J$9961),2,0)} -> 81 | F16: {=VLOOKUP($A16&$B$12,IF({1,0},成绩汇总表!$A$1:$A$9961&成绩汇总表!$B$1:$B$9961,成绩汇总表!$L$1:$L$9961),2,0)} -> 357 | H16: 外语 | I16: =INDEX(B16:G16,$H$13) -> 95 | J16: =INDEX(L16:V16,$H$13) -> 2 | K16: =IF(I16<60,I16,#N/A) -> #N/A | L16: {=VLOOKUP($A16&$B$12,IF({1,0},成绩汇总表!$A$1:$A$9961&成绩汇总表!$B$1:$B$9961,成绩汇总表!$E$1:$E$9961),2,0)} -> 2 | M16: {=VLOOKUP($A16&$B$12,IF({1,0},成绩汇总表!$A$1:$A$9961&成绩汇总表!$B$1:$B$9961,成绩汇总表!$G$1:$G$9961),2,0)} -> 1 | N16: {=VLOOKUP($A16&$B$12,IF({1,0},成绩汇总表!$A$1:$A$9961&成绩汇总表!$B$1:$B$9961,成绩汇总表!$I$1:$I$9961),2,0)} -> 5 | O16: {=VLOOKUP($A16&$B$12,IF({1,0},成绩汇总表!$A$1:$A$9961&成绩汇总表!$B$1:$B$9961,成绩汇总表!$K$1:$K$9961),2,0)} -> 9 | P16: {=VLOOKUP($A16&$B$12,IF({1,0},成绩汇总表!$A$1:$A$9961&成绩汇总表!$B$1:$B$9961,成绩汇总表!$M$1:$M$9961),2,0)} -> 4 | R16: =INDEX(B16:F16,$Q$13) -> 95 | S16: =INDEX(L16:P16,$Q$13) -> 2 | T16: =IF(R16<60,R16,NA()) -> #N/A
A17: 5月月考 | B17: {=VLOOKUP($A17&$B$12,IF({1,0},成绩汇总表!$A$1:$A$9961&成绩汇总表!$B$1:$B$9961,成绩汇总表!$D$1:$D$9961),2,0)} -> 55 | C17: {=VLOOKUP($A17&$B$12,IF({1,0},成绩汇总表!$A$1:$A$9961&成绩汇总表!$B$1:$B$9961,成绩汇总表!$F$1:$F$9961),2,0)} -> 85 | D17: {=VLOOKUP($A17&$B$12,IF({1,0},成绩汇总表!$A$1:$A$9961&成绩汇总表!$B$1:$B$9961,成绩汇总表!$H$1:$H$9961),2,0)} -> 55 | E17: {=VLOOKUP($A17&$B$12,IF({1,0},成绩汇总表!$A$1:$A$9961&成绩汇总表!$B$1:$B$9961,成绩汇总表!$J$1:$J$9961),2,0)} -> 95 | F17: {=VLOOKUP($A17&$B$12,IF({1,0},成绩汇总表!$A$1:$A$9961&成绩汇总表!$B$1:$B$9961,成绩汇总表!$L$1:$L$9961),2,0)} -> 290 | H17: 生物 | I17: =INDEX(B17:G17,$H$13) -> 55 | J17: =INDEX(L17:V17,$H$13) -> 10 | K17: =IF(I17<60,I17,#N/A) -> 55 | L17: {=VLOOKUP($A17&$B$12,IF({1,0},成绩汇总表!$A$1:$A$9961&成绩汇总表!$B$1:$B$9961,成绩汇总表!$E$1:$E$9961),2,0)} -> 10 | M17: {=VLOOKUP($A17&$B$12,IF({1,0},成绩汇总表!$A$1:$A$9961&成绩汇总表!$B$1:$B$9961,成绩汇总表!$G$1:$G$9961),2,0)} -> 6 | N17: {=VLOOKUP($A17&$B$12,IF({1,0},成绩汇总表!$A$1:$A$9961&成绩汇总表!$B$1:$B$9961,成绩汇总表!$I$1:$I$9961),2,0)} -> 9 | O17: {=VLOOKUP($A17&$B$12,IF({1,0},成绩汇总表!$A$1:$A$9961&成绩汇总表!$B$1:$B$9961,成绩汇总表!$K$1:$K$9961),2,0)} -> 2 | P17: {=VLOOKUP($A17&$B$12,IF({1,0},成绩汇总表!$A$1:$A$9961&成绩汇总表!$B$1:$B$9961,成绩汇总表!$M$1:$M$9961),2,0)} -> 10 | R17: =INDEX(B17:F17,$Q$13) -> 55 | S17: =INDEX(L17:P17,$Q$13) -> 10 | T17: =IF(R17<60,R17,NA()) -> 55
A18: 期末考试 | B18: {=VLOOKUP($A18&$B$12,IF({1,0},成绩汇总表!$A$1:$A$9961&成绩汇总表!$B$1:$B$9961,成绩汇总表!$D$1:$D$9961),2,0)} -> 85 | C18: {=VLOOKUP($A18&$B$12,IF({1,0},成绩汇总表!$A$1:$A$9961&成绩汇总表!$B$1:$B$9961,成绩汇总表!$F$1:$F$9961),2,0)} -> 95 | D18: {=VLOOKUP($A18&$B$12,IF({1,0},成绩汇总表!$A$1:$A$9961&成绩汇总表!$B$1:$B$9961,成绩汇总表!$H$1:$H$9961),2,0)} -> 95 | E18: {=VLOOKUP($A18&$B$12,IF({1,0},成绩汇总表!$A$1:$A$9961&成绩汇总表!$B$1:$B$9961,成绩汇总表!$J$1:$J$9961),2,0)} -> 86 | F18: {=VLOOKUP($A18&$B$12,IF({1,0},成绩汇总表!$A$1:$A$9961&成绩汇总表!$B$1:$B$9961,成绩汇总表!$L$1:$L$9961),2,0)} -> 361 | H18: 总分 | I18: =INDEX(B18:G18,$H$13) -> 85 | J18: =INDEX(L18:V18,$H$13) -> 6 | K18: =IF(I18<60,I18,#N/A) -> #N/A | L18: {=VLOOKUP($A18&$B$12,IF({1,0},成绩汇总表!$A$1:$A$9961&成绩汇总表!$B$1:$B$9961,成绩汇总表!$E$1:$E$9961),2,0)} -> 6 | M18: {=VLOOKUP($A18&$B$12,IF({1,0},成绩汇总表!$A$1:$A$9961&成绩汇总表!$B$1:$B$9961,成绩汇总表!$G$1:$G$9961),2,0)} -> 2 | N18: {=VLOOKUP($A18&$B$12,IF({1,0},成绩汇总表!$A$1:$A$9961&成绩汇总表!$B$1:$B$9961,成绩汇总表!$I$1:$I$9961),2,0)} -> 1 | O18: {=VLOOKUP($A18&$B$12,IF({1,0},成绩汇总表!$A$1:$A$9961&成绩汇总表!$B$1:$B$9961,成绩汇总表!$K$1:$K$9961),2,0)} -> 4 | P18: {=VLOOKUP($A18&$B$12,IF({1,0},成绩汇总表!$A$1:$A$9961&成绩汇总表!$B$1:$B$9961,成绩汇总表!$M$1:$M$9961),2,0)} -> 1 | R18: =INDEX(B18:F18,$Q$13) -> 85 | S18: =INDEX(L18:P18,$Q$13) -> 6 | T18: =IF(R18<60,R18,NA()) -> #N/A
D27: 每次成绩 与平均值对比分析 | O27: 每次成绩雷达图
A29: 2 | B29: 数学 | C29: 语文 | D29: 外语 | E29: 生物 | F29: 总分 | I29: 1 | J29: 数学 | K29: 语文 | L29: 外语 | M29: 生物 | N29: 总分
A30: =INDEX(A15:A24,A29) -> 期中考试 | B30: =INDEX(B15:B18,$A$29) -> 95 | C30: =INDEX(C15:C24,$A$29) -> 95 | D30: =INDEX(D15:D24,$A$29) -> 86 | E30: =INDEX(E15:E24,$A$29) -> 81 | I30: =INDEX(A15:A24,I29) -> 1月月考 | J30: =INDEX(L15:L24,$I$29) -> 9 | K30: =INDEX(M15:M24,$I$29) -> 4 | L30: =INDEX(N15:N24,$I$29) -> 2 | M30: =INDEX(O15:O24,$I$29) -> 7 | N30: =INDEX(P15:P24,$I$29) -> 7
F31: =INDEX(F15:F24,$A$29) -> 357
A32: 平均分 | B32: =INDEX(B4:B7,$A$29) -> 88.3 | C32: =INDEX(C4:C7,$A$29) -> 85.3 | D32: =INDEX(D4:D7,$A$29) -> 82.8 | E32: =INDEX(E4:E7,$A$29) -> 88.8 | F32: =INDEX(F4:F7,$A$29) -> 319.2

Sheet 学生信息汇总
A1: 学号 | B1: 姓名 | C1: 性别 | D1: 出生日期 | E1: 联系方式
A2: A01 | B2: 名字1 | C2: 男 | D2: 35796 | E2: 13190900101
A3: A02 | B3: 名字2 | C3: 女 | D3: 35797 | E3: 13190900101
A4: A03 | B4: 名字3 | C4: 男 | D4: 35798 | E4: 13190900101
A5: A04 | B5: 名字4 | C5: 女 | D5: 35799 | E5: 13190900101
A6: A05 | B6: 名字5 | C6: 男 | D6: 35800 | E6: 13190900101
A7: A06 | B7: 名字6 | C7: 女 | D7: 35801 | E7: 13190900101
A8: A07 | B8: 名字7 | C8: 男 | D8: 35802 | E8: 13190900101
A9: A08 | B9: 名字8 | C9: 女 | D9: 35803 | E9: 13190900101
A10: A09 | B10: 名字9 | C10: 男 | D10: 35804 | E10: 13190900101
A11: A10 | B11: 名字10 | C11: 女 | D11: 35805 | E11: 13190900101
A12: A11 | B12: 名字11 | C12: 男 | D12: 35806 | E12: 13190900101
A13: A12 | B13: 名字12 | C13: 女 | D13: 35807 | E13: 13190900101
... A21: A20 | B21: 名字20 | C21: 男 | D21: 35815 | E21: 13190900101
