Workbook

Sheet Sheet1
B2: data
B3: 州 | C3: 对比全美平均收入 | D3: 区域价格指数 | F3: 坐标轴刻度线方向标签
B4: Alabama | C4: =(参考数据!K3-参考数据!K$2)/参考数据!K$2 -> -0.090114111 | D4: 86.8 | F4: x | G4: y
B5: Alaska | C5: =(参考数据!K4-参考数据!K$2)/参考数据!K$2 -> 0.10660942 | D5: 105.6 | F5: 0.29 | G5: 100
B6: Arizona | C6: =(参考数据!K5-参考数据!K$2)/参考数据!K$2 -> -0.14825443 | D6: 96.2 | F6: 0 | G6: 120
B7: Arkansas | C7: =(参考数据!K6-参考数据!K$2)/参考数据!K$2 -> -0.076759688 | D7: 87.4
B8: California | C8: =(参考数据!K7-参考数据!K$2)/参考数据!K$2 -> -0.001852898 | D8: 113.4 | F8: 象限标签
B9: Colorado | C9: =(参考数据!K8-参考数据!K$2)/参考数据!K$2 -> 0.039792114 | D9: 103.2 | F9: x | G9: y
B10: Connecticut | C10: =(参考数据!K9-参考数据!K$2)/参考数据!K$2 -> 0.29974014 | D10: 108.7 | F10: 0.265 | G10: 116.5
B11: Delaware | C11: =(参考数据!K10-参考数据!K$2)/参考数据!K$2 -> -0.030233872 | D11: 100.4 | F11: -0.155 | G11: 116.5
B12: District of Columbia | C12: =(参考数据!K11-参考数据!K$2)/参考数据!K$2 -> 0.30929838 | D12: 117 | F12: -0.155 | G12: 83
B13: Florida | C13: =(参考数据!K12-参考数据!K$2)/参考数据!K$2 -> -0.055903288 | D13: 99.5 | F13: 0.265 | G13: 83
B14: Georgia | C14: =(参考数据!K13-参考数据!K$2)/参考数据!K$2 -> -0.083945317 | D14: 92.6
B15: Hawaii | C15: =(参考数据!K14-参考数据!K$2)/参考数据!K$2 -> -0.14961021 | D15: 118.8
B16: Idaho | C16: =(参考数据!K15-参考数据!K$2)/参考数据!K$2 -> -0.13966783 | D16: 93.4
B17: Illinois | C17: =(参考数据!K16-参考数据!K$2)/参考数据!K$2 -> 0.054276353 | D17: 99.7
B18: Indiana | C18: =(参考数据!K17-参考数据!K$2)/参考数据!K$2 -> -0.04650322 | D18: 90.7
B19: Iowa | C19: =(参考数据!K18-参考数据!K$2)/参考数据!K$2 -> 0.047542651 | D19: 90.3
B20: Kansas | C20: =(参考数据!K19-参考数据!K$2)/参考数据!K$2 -> 0.074387075 | D20: 90.4
B21: Kentucky | C21: =(参考数据!K20-参考数据!K$2)/参考数据!K$2 -> -0.10195458 | D21: 88.6
B22: Louisiana | C22: =(参考数据!K21-参考数据!K$2)/参考数据!K$2 -> -0.022099198 | D22: 90.6
B23: Maine | C23: =(参考数据!K22-参考数据!K$2)/参考数据!K$2 -> -0.096192521 | D23: 98
B24: Maryland | C24: =(参考数据!K23-参考数据!K$2)/参考数据!K$2 -> 0.061326404 | D24: 109.6
B25: Massachusetts | C25: =(参考数据!K24-参考数据!K$2)/参考数据!K$2 -> 0.21527511 | D25: 106.9
... B54: Wyoming | C54: =(参考数据!K53-参考数据!K$2)/参考数据!K$2 -> 0.2091741 | D54: 96.2

Sheet Sheet2
B2: data
B3: 州 | C3: 简写 | D3: 对比全美平均收入 | E3: 区域价格指数 | G3: 坐标轴刻度线方向标签
B4: Alabama | C4: AL | D4: =(参考数据!K3-参考数据!K$2)/参考数据!K$2 -> -0.090114111 | E4: 86.8 | G4: x | H4: y
B5: Alaska | C5: AK | D5: =(参考数据!K4-参考数据!K$2)/参考数据!K$2 -> 0.10660942 | E5: 105.6 | G5: 0.29 | H5: 100
B6: Arizona | C6: AZ | D6: =(参考数据!K5-参考数据!K$2)/参考数据!K$2 -> -0.14825443 | E6: 96.2 | G6: 0 | H6: 120
B7: Arkansas | C7: AR | D7: =(参考数据!K6-参考数据!K$2)/参考数据!K$2 -> -0.076759688 | E7: 87.4
B8: California | C8: CA | D8: =(参考数据!K7-参考数据!K$2)/参考数据!K$2 -> -0.001852898 | E8: 113.4 | G8: 象限标签
B9: Colorado | C9: CO | D9: =(参考数据!K8-参考数据!K$2)/参考数据!K$2 -> 0.039792114 | E9: 103.2 | G9: x | H9: y
B10: Connecticut | C10: CT | D10: =(参考数据!K9-参考数据!K$2)/参考数据!K$2 -> 0.29974014 | E10: 108.7 | G10: 0.265 | H10: 116.5
B11: Delaware | C11: DE | D11: =(参考数据!K10-参考数据!K$2)/参考数据!K$2 -> -0.030233872 | E11: 100.4 | G11: -0.155 | H11: 116.5
B12: District of Columbia | C12: DC | D12: =(参考数据!K11-参考数据!K$2)/参考数据!K$2 -> 0.30929838 | E12: 117 | G12: -0.155 | H12: 83
B13: Florida | C13: FL | D13: =(参考数据!K12-参考数据!K$2)/参考数据!K$2 -> -0.055903288 | E13: 99.5 | G13: 0.265 | H13: 83
B14: Georgia | C14: GA | D14: =(参考数据!K13-参考数据!K$2)/参考数据!K$2 -> -0.083945317 | E14: 92.6
B15: Hawaii | C15: HI | D15: =(参考数据!K14-参考数据!K$2)/参考数据!K$2 -> -0.14961021 | E15: 118.8
B16: Idaho | C16: ID | D16: =(参考数据!K15-参考数据!K$2)/参考数据!K$2 -> -0.13966783 | E16: 93.4
B17: Illinois | C17: IL | D17: =(参考数据!K16-参考数据!K$2)/参考数据!K$2 -> 0.054276353 | E17: 99.7
B18: Indiana | C18: IN | D18: =(参考数据!K17-参考数据!K$2)/参考数据!K$2 -> -0.04650322 | E18: 90.7
B19: Iowa | C19: IA | D19: =(参考数据!K18-参考数据!K$2)/参考数据!K$2 -> 0.047542651 | E19: 90.3
B20: Kansas | C20: KS | D20: =(参考数据!K19-参考数据!K$2)/参考数据!K$2 -> 0.074387075 | E20: 90.4
B21: Kentucky | C21: KY | D21: =(参考数据!K20-参考数据!K$2)/参考数据!K$2 -> -0.10195458 | E21: 88.6
B22: Louisiana | C22: LA | D22: =(参考数据!K21-参考数据!K$2)/参考数据!K$2 -> -0.022099198 | E22: 90.6
B23: Maine | C23: ME | D23: =(参考数据!K22-参考数据!K$2)/参考数据!K$2 -> -0.096192521 | E23: 98
B24: Maryland | C24: MD | D24: =(参考数据!K23-参考数据!K$2)/参考数据!K$2 -> 0.061326404 | E24: 109.6
B25: Massachusetts | C25: MA | D25: =(参考数据!K24-参考数据!K$2)/参考数据!K$2 -> 0.21527511 | E25: 106.9
... B54: Wyoming | C54: WY | D54: =(参考数据!K53-参考数据!K$2)/参考数据!K$2 -> 0.2091741 | E54: 96.2

Sheet Sheet3
B2: data
B3: 州 | C3: 简写 | D3: 东部西部 | E3: 对比全美平均收入 | F3: 区域价格指数 | H3: 坐标轴刻度线方向标签
B4: Alabama | C4: AL | D4: =IF(ISNUMBER(MATCH(C4,分区域!$C$3:$C$24,0)),"美国西部","美国东部") -> 美国东部 | E4: =(参考数据!K3-参考数据!K$2)/参考数据!K$2 -> -0.090114111 | F4: 86.8 | H4: x | I4: y
B5: Alaska | C5: AK | D5: =IF(ISNUMBER(MATCH(C5,分区域!$C$3:$C$24,0)),"美国西部","美国东部") -> 美国东部 | E5: =(参考数据!K4-参考数据!K$2)/参考数据!K$2 -> 0.10660942 | F5: 105.6 | H5: 0.29 | I5: 100
B6: Connecticut | C6: CT | D6: =IF(ISNUMBER(MATCH(C6,分区域!$C$3:$C$24,0)),"美国西部","美国东部") -> 美国东部 | E6: =(参考数据!K9-参考数据!K$2)/参考数据!K$2 -> 0.29974014 | F6: 108.7 | H6: 0 | I6: 120
B7: Delaware | C7: DE | D7: =IF(ISNUMBER(MATCH(C7,分区域!$C$3:$C$24,0)),"美国西部","美国东部") -> 美国东部 | E7: =(参考数据!K10-参考数据!K$2)/参考数据!K$2 -> -0.030233872 | F7: 100.4
B8: District of Columbia | C8: DC | D8: =IF(ISNUMBER(MATCH(C8,分区域!$C$3:$C$24,0)),"美国西部","美国东部") -> 美国东部 | E8: =(参考数据!K11-参考数据!K$2)/参考数据!K$2 -> 0.30929838 | F8: 117 | H8: 象限标签
B9: Florida | C9: FL | D9: =IF(ISNUMBER(MATCH(C9,分区域!$C$3:$C$24,0)),"美国西部","美国东部") -> 美国东部 | E9: =(参考数据!K12-参考数据!K$2)/参考数据!K$2 -> -0.055903288 | F9: 99.5 | H9: x | I9: y
B10: Georgia | C10: GA | D10: =IF(ISNUMBER(MATCH(C10,分区域!$C$3:$C$24,0)),"美国西部","美国东部") -> 美国东部 | E10: =(参考数据!K13-参考数据!K$2)/参考数据!K$2 -> -0.083945317 | F10: 92.6 | H10: 0.265 | I10: 116.5
B11: Hawaii | C11: HI | D11: =IF(ISNUMBER(MATCH(C11,分区域!$C$3:$C$24,0)),"美国西部","美国东部") -> 美国东部 | E11: =(参考数据!K14-参考数据!K$2)/参考数据!K$2 -> -0.14961021 | F11: 118.8 | H11: -0.155 | I11: 116.5
B12: Illinois | C12: IL | D12: =IF(ISNUMBER(MATCH(C12,分区域!$C$3:$C$24,0)),"美国西部","美国东部") -> 美国东部 | E12: =(参考数据!K16-参考数据!K$2)/参考数据!K$2 -> 0.054276353 | F12: 99.7 | H12: -0.155 | I12: 83
B13: Indiana | C13: IN | D13: =IF(ISNUMBER(MATCH(C13,分区域!$C$3:$C$24,0)),"美国西部","美国东部") -> 美国东部 | E13: =(参考数据!K17-参考数据!K$2)/参考数据!K$2 -> -0.04650322 | F13: 90.7 | H13: 0.265 | I13: 83
B14: Kentucky | C14: KY | D14: =IF(ISNUMBER(MATCH(C14,分区域!$C$3:$C$24,0)),"美国西部","美国东部") -> 美国东部 | E14: =(参考数据!K20-参考数据!K$2)/参考数据!K$2 -> -0.10195458 | F14: 88.6
B15: Maine | C15: ME | D15: =IF(ISNUMBER(MATCH(C15,分区域!$C$3:$C$24,0)),"美国西部","美国东部") -> 美国东部 | E15: =(参考数据!K22-参考数据!K$2)/参考数据!K$2 -> -0.096192521 | F15: 98
B16: Maryland | C16: MD | D16: =IF(ISNUMBER(MATCH(C16,分区域!$C$3:$C$24,0)),"美国西部","美国东部") -> 美国东部 | E16: =(参考数据!K23-参考数据!K$2)/参考数据!K$2 -> 0.061326404 | F16: 109.6
B17: Massachusetts | C17: MA | D17: =IF(ISNUMBER(MATCH(C17,分区域!$C$3:$C$24,0)),"美国西部","美国东部") -> 美国东部 | E17: =(参考数据!K24-参考数据!K$2)/参考数据!K$2 -> 0.21527511 | F17: 106.9
B18: Michigan | C18: MI | D18: =IF(ISNUMBER(MATCH(C18,分区域!$C$3:$C$24,0)),"美国西部","美国东部") -> 美国东部 | E18: =(参考数据!K25-参考数据!K$2)/参考数据!K$2 -> -0.047045532 | F18: 93.5
B19: Mississippi | C19: MS | D19: =IF(ISNUMBER(MATCH(C19,分区域!$C$3:$C$24,0)),"美国西部","美国东部") -> 美国东部 | E19: =(参考数据!K27-参考数据!K$2)/参考数据!K$2 -> -0.16644447 | F19: 86.2
B20: New Hampshire | C20: NH | D20: =IF(ISNUMBER(MATCH(C20,分区域!$C$3:$C$24,0)),"美国西部","美国东部") -> 美国东部 | E20: =(参考数据!K32-参考数据!K$2)/参考数据!K$2 -> 0.074002938 | F20: 105
B21: New Jersey | C21: NJ | D21: =IF(ISNUMBER(MATCH(C21,分区域!$C$3:$C$24,0)),"美国西部","美国东部") -> 美国东部 | E21: =(参考数据!K33-参考数据!K$2)/参考数据!K$2 -> 0.097955033 | F21: 113.4
B22: New York | C22: NY | D22: =IF(ISNUMBER(MATCH(C22,分区域!$C$3:$C$24,0)),"美国西部","美国东部") -> 美国东部 | E22: =(参考数据!K35-参考数据!K$2)/参考数据!K$2 -> 0.049485934 | F22: 115.3
B23: North Carolina | C23: NC | D23: =IF(ISNUMBER(MATCH(C23,分区域!$C$3:$C$24,0)),"美国西部","美国东部") -> 美国东部 | E23: =(参考数据!K36-参考数据!K$2)/参考数据!K$2 -> -0.061529771 | F23: 91.2
B24: Ohio | C24: OH | D24: =IF(ISNUMBER(MATCH(C24,分区域!$C$3:$C$24,0)),"美国西部","美国东部") -> 美国东部 | E24: =(参考数据!K38-参考数据!K$2)/参考数据!K$2 -> 0.015546266 | F24: 89.2
B25: Pennsylvania | C25: PA | D25: =IF(ISNUMBER(MATCH(C25,分区域!$C$3:$C$24,0)),"美国西部","美国东部") -> 美国东部 | E25: =(参考数据!K41-参考数据!K$2)/参考数据!K$2 -> 0.051564795 | F25: 97.9
B26: Rhode Island | C26: RI | D26: =IF(ISNUMBER(MATCH(C26,分区域!$C$3:$C$24,0)),"美国西部","美国东部") -> 美国东部 | E26: =(参考数据!K42-参考数据!K$2)/参考数据!K$2 -> 0.042119535 | F26: 98.7
B27: South Carolina | C27: SC | D27: =IF(ISNUMBER(MATCH(C27,分区域!$C$3:$C$24,0)),"美国西部","美国东部") -> 美国东部 | E27: =(参考数据!K43-参考数据!K$2)/参考数据!K$2 -> -0.11178398 | F27: 90.3
B28: Tennessee | C28: TN | D28: =IF(ISNUMBER(MATCH(C28,分区域!$C$3:$C$24,0)),"美国西部","美国东部") -> 美国东部 | E28: =(参考数据!K45-参考数据!K$2)/参考数据!K$2 -> -0.030572817 | F28: 89.9
B29: Vermont | C29: VT | D29: =IF(ISNUMBER(MATCH(C29,分区域!$C$3:$C$24,0)),"美国西部","美国东部") -> 美国东部 | E29: =(参考数据!K48-参考数据!K$2)/参考数据!K$2 -> -0.0053327308 | F29: 101.6
B30: Virginia | C30: VA | D30: =IF(ISNUMBER(MATCH(C30,分区域!$C$3:$C$24,0)),"美国西部","美国东部") -> 美国东部 | E30: =(参考数据!K49-参考数据!K$2)/参考数据!K$2 -> 0.052581629 | F30: 102.5
B31: West Virginia | C31: WV | D31: =IF(ISNUMBER(MATCH(C31,分区域!$C$3:$C$24,0)),"美国西部","美国东部") -> 美国东部 | E31: =(参考数据!K51-参考数据!K$2)/参考数据!K$2 -> -0.14988137 | F31: 88.9
B32: Wisconsin | C32: WI | D32: =IF(ISNUMBER(MATCH(C32,分区域!$C$3:$C$24,0)),"美国西部","美国东部") -> 美国东部 | E32: =(参考数据!K52-参考数据!K$2)/参考数据!K$2 -> 0.0202463 | F32: 93.1
B33: Wyoming | C33: WY | D33: =IF(ISNUMBER(MATCH(C33,分区域!$C$3:$C$24,0)),"美国西部","美国东部") -> 美国东部 | E33: =(参考数据!K53-参考数据!K$2)/参考数据!K$2 -> 0.2091741 | F33: 96.2
B34: Arizona | C34: AZ | D34: =IF(ISNUMBER(MATCH(C34,分区域!$C$3:$C$24,0)),"美国西部","美国东部") -> 美国西部 | E34: =(参考数据!K5-参考数据!K$2)/参考数据!K$2 -> -0.14825443 | F34: 96.2
B35: Arkansas | C35: AR | D35: =IF(ISNUMBER(MATCH(C35,分区域!$C$3:$C$24,0)),"美国西部","美国东部") -> 美国西部 | E35: =(参考数据!K6-参考数据!K$2)/参考数据!K$2 -> -0.076759688 | F35: 87.4
B36: California | C36: CA | D36: =IF(ISNUMBER(MATCH(C36,分区域!$C$3:$C$24,0)),"美国西部","美国东部") -> 美国西部 | E36: =(参考数据!K7-参考数据!K$2)/参考数据!K$2 -> -0.001852898 | F36: 113.4
B37: Colorado | C37: CO | D37: =IF(ISNUMBER(MATCH(C37,分区域!$C$3:$C$24,0)),"美国西部","美国东部") -> 美国西部 | E37: =(参考数据!K8-参考数据!K$2)/参考数据!K$2 -> 0.039792114 | F37: 103.2
B38: Idaho | C38: ID | D38: =IF(ISNUMBER(MATCH(C38,分区域!$C$3:$C$24,0)),"美国西部","美国东部") -> 美国西部 | E38: =(参考数据!K15-参考数据!K$2)/参考数据!K$2 -> -0.13966783 | F38: 93.4
B39: Iowa | C39: IA | D39: =IF(ISNUMBER(MATCH(C39,分区域!$C$3:$C$24,0)),"美国西部","美国东部") -> 美国西部 | E39: =(参考数据!K18-参考数据!K$2)/参考数据!K$2 -> 0.047542651 | F39: 90.3
B40: Kansas | C40: KS | D40: =IF(ISNUMBER(MATCH(C40,分区域!$C$3:$C$24,0)),"美国西部","美国东部") -> 美国西部 | E40: =(参考数据!K19-参考数据!K$2)/参考数据!K$2 -> 0.074387075 | F40: 90.4
B41: Louisiana | C41: LA | D41: =IF(ISNUMBER(MATCH(C41,分区域!$C$3:$C$24,0)),"美国西部","美国东部") -> 美国西部 | E41: =(参考数据!K21-参考数据!K$2)/参考数据!K$2 -> -0.022099198 | F41: 90.6
...

Sheet Sheet4
B2: data | K2: 堆积柱形图辅助系列 | O2: 散点辅助添加误差线
B3: 州 | C3: 简写 | D3: 东部西部 | E3: 对比全美平均收入 | F3: 区域价格指数 | H3: 坐标轴刻度线方向标签 | K3: 上柱形 | L3: 下柱形 | M3: 辅助 | O3: x | P3: y | Q3: 误差量
B4: Alabama | C4: AL | D4: =IF(ISNUMBER(MATCH(C4,分区域!$C$3:$C$24,0)),"美国西部","美国东部") -> 美国东部 | E4: =(参考数据!K3-参考数据!K$2)/参考数据!K$2 -> -0.090114111 | F4: 86.8 | H4: x | I4: y | K4: 20 | M4: 20 | O4: -0.2 | P4: 100 | Q4: 20
B5: Alaska | C5: AK | D5: =IF(ISNUMBER(MATCH(C5,分区域!$C$3:$C$24,0)),"美国西部","美国东部") -> 美国东部 | E5: =(参考数据!K4-参考数据!K$2)/参考数据!K$2 -> 0.10660942 | F5: 105.6 | H5: 0.29 | I5: 100 | K5: 20 | M5: 20 | O5: -0.19 | P5: 100 | Q5: 20 | AE5: 贴入形状：底层是形状
B6: Connecticut | C6: CT | D6: =IF(ISNUMBER(MATCH(C6,分区域!$C$3:$C$24,0)),"美国西部","美国东部") -> 美国东部 | E6: =(参考数据!K9-参考数据!K$2)/参考数据!K$2 -> 0.29974014 | F6: 108.7 | H6: 0 | I6: 120 | K6: 20 | M6: 20 | O6: -0.18 | P6: 100 | Q6: 20
B7: Delaware | C7: DE | D7: =IF(ISNUMBER(MATCH(C7,分区域!$C$3:$C$24,0)),"美国西部","美国东部") -> 美国东部 | E7: =(参考数据!K10-参考数据!K$2)/参考数据!K$2 -> -0.030233872 | F7: 100.4 | K7: 20 | M7: 20 | O7: -0.17 | P7: 100 | Q7: 20
B8: District of Columbia | C8: DC | D8: =IF(ISNUMBER(MATCH(C8,分区域!$C$3:$C$24,0)),"美国西部","美国东部") -> 美国东部 | E8: =(参考数据!K11-参考数据!K$2)/参考数据!K$2 -> 0.30929838 | F8: 117 | H8: 象限标签 | K8: 20 | M8: 20 | O8: -0.16 | P8: 100 | Q8: 20
B9: Florida | C9: FL | D9: =IF(ISNUMBER(MATCH(C9,分区域!$C$3:$C$24,0)),"美国西部","美国东部") -> 美国东部 | E9: =(参考数据!K12-参考数据!K$2)/参考数据!K$2 -> -0.055903288 | F9: 99.5 | H9: x | I9: y | K9: 20 | M9: 20 | O9: -0.15 | P9: 100 | Q9: 20
B10: Georgia | C10: GA | D10: =IF(ISNUMBER(MATCH(C10,分区域!$C$3:$C$24,0)),"美国西部","美国东部") -> 美国东部 | E10: =(参考数据!K13-参考数据!K$2)/参考数据!K$2 -> -0.083945317 | F10: 92.6 | H10: 0.265 | I10: 116.5 | K10: 20 | M10: 20 | O10: -0.14 | P10: 100 | Q10: 20
B11: Hawaii | C11: HI | D11: =IF(ISNUMBER(MATCH(C11,分区域!$C$3:$C$24,0)),"美国西部","美国东部") -> 美国东部 | E11: =(参考数据!K14-参考数据!K$2)/参考数据!K$2 -> -0.14961021 | F11: 118.8 | H11: -0.155 | I11: 116.5 | K11: 20 | M11: 20 | O11: -0.13 | P11: 100 | Q11: 20
B12: Illinois | C12: IL | D12: =IF(ISNUMBER(MATCH(C12,分区域!$C$3:$C$24,0)),"美国西部","美国东部") -> 美国东部 | E12: =(参考数据!K16-参考数据!K$2)/参考数据!K$2 -> 0.054276353 | F12: 99.7 | H12: -0.155 | I12: 83 | K12: 20 | M12: 20 | O12: -0.12 | P12: 100 | Q12: 20
B13: Indiana | C13: IN | D13: =IF(ISNUMBER(MATCH(C13,分区域!$C$3:$C$24,0)),"美国西部","美国东部") -> 美国东部 | E13: =(参考数据!K17-参考数据!K$2)/参考数据!K$2 -> -0.04650322 | F13: 90.7 | H13: 0.265 | I13: 83 | K13: 20 | M13: 20 | O13: -0.11 | P13: 100 | Q13: 20
B14: Kentucky | C14: KY | D14: =IF(ISNUMBER(MATCH(C14,分区域!$C$3:$C$24,0)),"美国西部","美国东部") -> 美国东部 | E14: =(参考数据!K20-参考数据!K$2)/参考数据!K$2 -> -0.10195458 | F14: 88.6 | K14: 20 | M14: 20 | O14: -0.1 | P14: 100 | Q14: 20
B15: Maine | C15: ME | D15: =IF(ISNUMBER(MATCH(C15,分区域!$C$3:$C$24,0)),"美国西部","美国东部") -> 美国东部 | E15: =(参考数据!K22-参考数据!K$2)/参考数据!K$2 -> -0.096192521 | F15: 98 | K15: 20 | M15: 20 | O15: -0.09 | P15: 100 | Q15: 20
B16: Maryland | C16: MD | D16: =IF(ISNUMBER(MATCH(C16,分区域!$C$3:$C$24,0)),"美国西部","美国东部") -> 美国东部 | E16: =(参考数据!K23-参考数据!K$2)/参考数据!K$2 -> 0.061326404 | F16: 109.6 | K16: 20 | M16: 20 | O16: -0.08 | P16: 100 | Q16: 20
B17: Massachusetts | C17: MA | D17: =IF(ISNUMBER(MATCH(C17,分区域!$C$3:$C$24,0)),"美国西部","美国东部") -> 美国东部 | E17: =(参考数据!K24-参考数据!K$2)/参考数据!K$2 -> 0.21527511 | F17: 106.9 | K17: 20 | M17: 20 | O17: -0.07 | P17: 100 | Q17: 20
B18: Michigan | C18: MI | D18: =IF(ISNUMBER(MATCH(C18,分区域!$C$3:$C$24,0)),"美国西部","美国东部") -> 美国东部 | E18: =(参考数据!K25-参考数据!K$2)/参考数据!K$2 -> -0.047045532 | F18: 93.5 | K18: 20 | M18: 20 | O18: -0.06 | P18: 100 | Q18: 20
B19: Mississippi | C19: MS | D19: =IF(ISNUMBER(MATCH(C19,分区域!$C$3:$C$24,0)),"美国西部","美国东部") -> 美国东部 | E19: =(参考数据!K27-参考数据!K$2)/参考数据!K$2 -> -0.16644447 | F19: 86.2 | K19: 20 | M19: 20 | O19: -0.05 | P19: 100 | Q19: 20
B20: New Hampshire | C20: NH | D20: =IF(ISNUMBER(MATCH(C20,分区域!$C$3:$C$24,0)),"美国西部","美国东部") -> 美国东部 | E20: =(参考数据!K32-参考数据!K$2)/参考数据!K$2 -> 0.074002938 | F20: 105 | K20: 20 | M20: 20 | O20: -0.04 | P20: 100 | Q20: 20
B21: New Jersey | C21: NJ | D21: =IF(ISNUMBER(MATCH(C21,分区域!$C$3:$C$24,0)),"美国西部","美国东部") -> 美国东部 | E21: =(参考数据!K33-参考数据!K$2)/参考数据!K$2 -> 0.097955033 | F21: 113.4 | K21: 20 | M21: 20 | O21: -0.03 | P21: 100 | Q21: 20
B22: New York | C22: NY | D22: =IF(ISNUMBER(MATCH(C22,分区域!$C$3:$C$24,0)),"美国西部","美国东部") -> 美国东部 | E22: =(参考数据!K35-参考数据!K$2)/参考数据!K$2 -> 0.049485934 | F22: 115.3 | K22: 20 | M22: 20 | O22: -0.02 | P22: 100 | Q22: 20
B23: North Carolina | C23: NC | D23: =IF(ISNUMBER(MATCH(C23,分区域!$C$3:$C$24,0)),"美国西部","美国东部") -> 美国东部 | E23: =(参考数据!K36-参考数据!K$2)/参考数据!K$2 -> -0.061529771 | F23: 91.2 | K23: 20 | M23: 20 | O23: -0.01 | P23: 100 | Q23: 20
B24: Ohio | C24: OH | D24: =IF(ISNUMBER(MATCH(C24,分区域!$C$3:$C$24,0)),"美国西部","美国东部") -> 美国东部 | E24: =(参考数据!K38-参考数据!K$2)/参考数据!K$2 -> 0.015546266 | F24: 89.2 | L24: 20 | M24: 20 | O24: -0.006 | P24: 100 | Q24: 20
B25: Pennsylvania | C25: PA | D25: =IF(ISNUMBER(MATCH(C25,分区域!$C$3:$C$24,0)),"美国西部","美国东部") -> 美国东部 | E25: =(参考数据!K41-参考数据!K$2)/参考数据!K$2 -> 0.051564795 | F25: 97.9 | L25: 20 | M25: 20 | O25: 0.006 | P25: 100 | Q25: -20
B26: Rhode Island | C26: RI | D26: =IF(ISNUMBER(MATCH(C26,分区域!$C$3:$C$24,0)),"美国西部","美国东部") -> 美国东部 | E26: =(参考数据!K42-参考数据!K$2)/参考数据!K$2 -> 0.042119535 | F26: 98.7 | L26: 20 | M26: 20 | O26: 0.01 | P26: 100 | Q26: -20
B27: South Carolina | C27: SC | D27: =IF(ISNUMBER(MATCH(C27,分区域!$C$3:$C$24,0)),"美国西部","美国东部") -> 美国东部 | E27: =(参考数据!K43-参考数据!K$2)/参考数据!K$2 -> -0.11178398 | F27: 90.3 | L27: 20 | M27: 20 | O27: 0.02 | P27: 100 | Q27: -20
B28: Tennessee | C28: TN | D28: =IF(ISNUMBER(MATCH(C28,分区域!$C$3:$C$24,0)),"美国西部","美国东部") -> 美国东部 | E28: =(参考数据!K45-参考数据!K$2)/参考数据!K$2 -> -0.030572817 | F28: 89.9 | L28: 20 | M28: 20 | O28: 0.03 | P28: 100 | Q28: -20
B29: Vermont | C29: VT | D29: =IF(ISNUMBER(MATCH(C29,分区域!$C$3:$C$24,0)),"美国西部","美国东部") -> 美国东部 | E29: =(参考数据!K48-参考数据!K$2)/参考数据!K$2 -> -0.0053327308 | F29: 101.6 | L29: 20 | M29: 20 | O29: 0.04 | P29: 100 | Q29: -20
B30: Virginia | C30: VA | D30: =IF(ISNUMBER(MATCH(C30,分区域!$C$3:$C$24,0)),"美国西部","美国东部") -> 美国东部 | E30: =(参考数据!K49-参考数据!K$2)/参考数据!K$2 -> 0.052581629 | F30: 102.5 | L30: 20 | M30: 20 | O30: 0.05 | P30: 100 | Q30: -20
B31: West Virginia | C31: WV | D31: =IF(ISNUMBER(MATCH(C31,分区域!$C$3:$C$24,0)),"美国西部","美国东部") -> 美国东部 | E31: =(参考数据!K51-参考数据!K$2)/参考数据!K$2 -> -0.14988137 | F31: 88.9 | L31: 20 | M31: 20 | O31: 0.06 | P31: 100 | Q31: -20
B32: Wisconsin | C32: WI | D32: =IF(ISNUMBER(MATCH(C32,分区域!$C$3:$C$24,0)),"美国西部","美国东部") -> 美国东部 | E32: =(参考数据!K52-参考数据!K$2)/参考数据!K$2 -> 0.0202463 | F32: 93.1 | L32: 20 | M32: 20 | O32: 0.07 | P32: 100 | Q32: -20
B33: Wyoming | C33: WY | D33: =IF(ISNUMBER(MATCH(C33,分区域!$C$3:$C$24,0)),"美国西部","美国东部") -> 美国东部 | E33: =(参考数据!K53-参考数据!K$2)/参考数据!K$2 -> 0.2091741 | F33: 96.2 | L33: 20 | M33: 20 | O33: 0.08 | P33: 100 | Q33: -20
B34: Arizona | C34: AZ | D34: =IF(ISNUMBER(MATCH(C34,分区域!$C$3:$C$24,0)),"美国西部","美国东部") -> 美国西部 | E34: =(参考数据!K5-参考数据!K$2)/参考数据!K$2 -> -0.14825443 | F34: 96.2 | L34: 20 | M34: 20 | O34: 0.09 | P34: 100 | Q34: -20
B35: Arkansas | C35: AR | D35: =IF(ISNUMBER(MATCH(C35,分区域!$C$3:$C$24,0)),"美国西部","美国东部") -> 美国西部 | E35: =(参考数据!K6-参考数据!K$2)/参考数据!K$2 -> -0.076759688 | F35: 87.4 | L35: 20 | M35: 20 | O35: 0.1 | P35: 100 | Q35: -20
B36: California | C36: CA | D36: =IF(ISNUMBER(MATCH(C36,分区域!$C$3:$C$24,0)),"美国西部","美国东部") -> 美国西部 | E36: =(参考数据!K7-参考数据!K$2)/参考数据!K$2 -> -0.001852898 | F36: 113.4 | L36: 20 | M36: 20 | O36: 0.11 | P36: 100 | Q36: -20 | AE36: 加入堆积柱形图系列
B37: Colorado | C37: CO | D37: =IF(ISNUMBER(MATCH(C37,分区域!$C$3:$C$24,0)),"美国西部","美国东部") -> 美国西部 | E37: =(参考数据!K8-参考数据!K$2)/参考数据!K$2 -> 0.039792114 | F37: 103.2 | L37: 20 | M37: 20 | O37: 0.12 | P37: 100 | Q37: -20
B38: Idaho | C38: ID | D38: =IF(ISNUMBER(MATCH(C38,分区域!$C$3:$C$24,0)),"美国西部","美国东部") -> 美国西部 | E38: =(参考数据!K15-参考数据!K$2)/参考数据!K$2 -> -0.13966783 | F38: 93.4 | L38: 20 | M38: 20 | O38: 0.13 | P38: 100 | Q38: -20
B39: Iowa | C39: IA | D39: =IF(ISNUMBER(MATCH(C39,分区域!$C$3:$C$24,0)),"美国西部","美国东部") -> 美国西部 | E39: =(参考数据!K18-参考数据!K$2)/参考数据!K$2 -> 0.047542651 | F39: 90.3 | L39: 20 | M39: 20 | O39: 0.14 | P39: 100 | Q39: -20
B40: Kansas | C40: KS | D40: =IF(ISNUMBER(MATCH(C40,分区域!$C$3:$C$24,0)),"美国西部","美国东部") -> 美国西部 | E40: =(参考数据!K19-参考数据!K$2)/参考数据!K$2 -> 0.074387075 | F40: 90.4 | L40: 20 | M40: 20 | O40: 0.15 | P40: 100 | Q40: -20
B41: Louisiana | C41: LA | D41: =IF(ISNUMBER(MATCH(C41,分区域!$C$3:$C$24,0)),"美国西部","美国东部") -> 美国西部 | E41: =(参考数据!K21-参考数据!K$2)/参考数据!K$2 -> -0.022099198 | F41: 90.6 | L41: 20 | M41: 20 | O41: 0.16 | P41: 100 | Q41: -20
...

Sheet Sheet5

Sheet 参考数据
A1: GeoFips | B1: GeoName | C1: LineCode | D1: 2008 | E1: 2009 | F1: 2010 | G1: 2011 | H1: 2012 | I1: 2013 | J1: 2014 | K1: 2015
A2: 00000 | B2: United States | C2: 2 | D2: 41055 | E2: 39376 | F2: 39622 | G2: 40769 | H2: 41728 | I2: 41377 | J2: 42594 | K2: 44255
A3: 01000 | B3: Alabama | C3: 2 | D3: 38228 | E3: 37476 | F3: 37782 | G3: 38104 | H3: 38035 | I3: 37982 | J3: 38806 | K3: 40267
A4: 02000 | B4: Alaska | C4: 2 | D4: 44815 | E4: 43948 | F4: 45441 | G4: 47071 | H4: 47161 | I4: 45685 | J4: 47140 | K4: 48973
A5: 04000 | B5: Arizona | C5: 2 | D5: 35578 | E5: 33810 | F5: 33561 | G5: 34326 | H5: 35046 | I5: 35307 | J5: 36277 | K5: 37694
A6: 05000 | B6: Arkansas | C6: 2 | D6: 37049 | E6: 36317 | F6: 35765 | G6: 37100 | H6: 38885 | I6: 38186 | J6: 40026 | K6: 40858
A7: 06000 | B7: California | C7: 2 | D7: 39143 | E7: 37524 | F7: 37590 | G7: 38922 | H7: 40447 | I7: 40015 | J7: 41537 | K7: 44173
A8: 08000 | B8: Colorado | C8: 2 | D8: 42576 | E8: 39522 | F8: 39000 | G8: 40768 | H8: 42085 | I8: 42742 | J8: 44709 | K8: 46016
A9: 09000 | B9: Connecticut | C9: 2 | D9: 55457 | E9: 54920 | F9: 55979 | G9: 56370 | H9: 56210 | I9: 55071 | J9: 56207 | K9: 57520
A10: 10000 | B10: Delaware | C10: 2 | D10: 41103 | E10: 40152 | F10: 39394 | G10: 41314 | H10: 40632 | I10: 40588 | J10: 40815 | K10: 42917
A11: 11000 | B11: District of Columbia | C11: 2 | D11: 53820 | E11: 51699 | F11: 51581 | G11: 53746 | H11: 53411 | I11: 52981 | J11: 54462 | K11: 57943
A12: 12000 | B12: Florida | C12: 2 | D12: 39416 | E12: 37174 | F12: 38442 | G12: 39268 | H12: 39057 | I12: 38307 | J12: 39733 | K12: 41781
A13: 13000 | B13: Georgia | C13: 2 | D13: 37824 | E13: 37027 | F13: 37009 | G13: 38381 | H13: 37753 | I13: 37504 | J13: 39009 | K13: 40540
... A53: 56000 | B53: Wyoming | C53: 2 | D53: 50597 | E53: 45464 | F53: 46730 | G53: 49252 | H53: 52021 | I53: 51152 | J53: 53504 | K53: 53512

Sheet 参考资料
B2: 美国州名 | C2: 美国州名英文 | D2: 美国州名简写和简称 | E2: 首府 | F2: 首府英文名
B3: 阿拉巴马州 | C3: Alabama | D3: AL | E3: 蒙哥马利 | F3: Montgomery
B4: 阿拉斯加州 | C4: Alaska | D4: AK | E4: 朱诺 | F4: Juneau
B5: 亚利桑那州 | C5: Arizona | D5: AZ | E5: 菲尼克斯 | F5: Phoenix
B6: 阿肯色州 | C6: Arkansas | D6: AR | E6: 小石城 | F6: Little rock
B7: 加利福尼亚州 | C7: California | D7: CA | E7: 萨克拉门托 | F7: Sacramento
B8: 科罗拉多州 | C8: Colorado | D8: CO | E8: 丹佛 | F8: Denver
B9: 康涅狄格州 | C9: Connecticut | D9: CT | E9: 哈特福德 | F9: Hartford
B10: 特拉华州 | C10: Delaware | D10: DE | E10: 多佛 | F10: Dover
B11: 佛罗里达州 | C11: Florida | D11: FL | E11: 塔拉哈西 | F11: Tallahassee
B12: 乔治亚州 | C12: Georgia | D12: GA | E12: 亚特兰大 | F12: Atlanta
B13: 夏威夷州 | C13: Hawaii | D13: HI | E13: 檀香山 | F13: Honolulu
... B52: 怀俄明州 | C52: Wyoming | D52: WY | E52: 夏延 | F52: Cheyenne

Sheet 分区域
A1: 美国西部（密西西比河以西）
A2: 州中文名 | B2: 州英文名 | C2: 州简称
A3: 华盛顿州 | B3: Washington | C3: WA
A4: 俄勒冈州 | B4: Oregon | C4: OR
A5: 加利福尼亚州 | B5: California | C5: CA
A6: 内华达州 | B6: Nevada | C6: NV
A7: 爱达荷州 | B7: Idaho | C7: ID
A8: 犹他州 | B8: Utah | C8: UT
A9: 亚利桑那州 | B9: Arizona | C9: AZ
A10: 蒙大拿州 | B10: Montana | C10: MT
A11: 怀俄明州 | B11: Wyoming | C11: MY
A12: 科罗拉多州 | B12: Colorado | C12: CO
A13: 新墨西哥州 | B13: New Mexico | C13: NM
... A24: 路易斯安那州 | B24: Louisiana | C24: LA
A26: 美国东部（密西西比河以东）
A27: 州中文名 | B27: 州英文名 | C27: 州简称
A28: 威斯康星州 | B28: Wisconsin | C28: WI
A29: 伊利诺州 | B29: Illinois | C29: IL
A30: 田纳西州 | B30: Tennessee | C30: TN
A31: 密西西比州 | B31: Mississippi | C31: MS
A32: 密歇根州 | B32: Michigan | C32: MI
A33: 印第安那州 | B33: Indiana | C33: ID
A34: 肯塔基州 | B34: Kentucky | C34: KY
A35: 阿拉巴马州 | B35: Alabama | C35: AL
A36: 俄亥俄州 | B36: Ohio | C36: OH
A37: 西弗吉尼亚州 | B37: West Virginia | C37: WV
A38: 弗吉尼亚州 | B38: Virginia | C38: VA
... A54: 佛蒙特州 | B54: Vermont | C54: VT
